Workbook
Name s_gennemsnitspris_alle_og_melder: TEST_STATISTIK_02_KR!$B$96:$G$107

Sheet 00_Regnskab_01
B1: ok? | C1: Dato | D1: Person | H1: Samlet sum | I1: Antal spil | J1: Største gevinst | K1: Største tab
D2: Thomas | E2: Peter | F2: Janus | G2: Christian | M2: Regnskab
A3: 1 | C3: 42542 | D3: -230 | E3: -166 | F3: 370 | G3: 8 | H3: =sum(D3+F3+E3+G3) -> -18 | I3: 24 | L3: Thomas, Vanløse | M3: Christians bog | N3: foto
A4: 2 | B4: x | C4: 42637 | D4: 544 | E4: -872 | F4: 472 | G4: -258 | H4: =sum(D4+F4+E4+G4) -> -114 | I4: 46 | L4: Christian, Østerbro | M4: Christians bog | N4: Messenger-tråd (billeder af snapseflasker)
A5: 3 | C5: 42791 | D5: 54 | E5: 234 | F5: 148 | G5: -404 | H5: =sum(D5+F5+E5+G5) -> 32 | I5: 23 | L5: Måske 25/2/2017 hos Peter (Lundtoftevej 208) | M5: Christians bog
A6: 4 | C6: ? | D6: -72 | E6: -256 | F6: 138 | G6: 186 | H6: =sum(D6+F6+E6+G6) -> -4 | I6: 30 | L6: ? | M6: Christians bog | N6: Kunne det være første dag i Berlin? Passer ikke rigtig med Peters og Christians regnskab… Jeg har en svag erindring om, at vi nulstillede optællingen halvvejs, fordi Christian var så langt bagefter, at han havde det lidt tungt med motivationen…? Men det er nok mere sandsynligt, at det er første del af regnskabet fra Berlin-turen (fredag) og at der mangler en mellemregning fra bogen til starten i Peters regneark…
A7: 5 | C7: 43000 | L7: Janus, Berlin | N7: Fredag er tom i regnearket, men vi starter ikke på nul, så det er nok videreført fra dagen før (J: 140 / T: -84 / P: -68 / C: 12)
A8: 6 | B8: x | C8: 43001 | D8: -398 | E8: 106 | F8: 554 | G8: -262 | H8: =sum(D8+F8+E8+G8) -> 0 | I8: 26 | L8: Janus, Berlin | M8: whistberlin.xlsx
A9: 7 | B9: x | C9: 43002 | D9: -56 | E9: -8 | F9: 32 | G9: 32 | H9: =sum(D9+F9+E9+G9) -> 0 | I9: 11 | L9: Janus, Berlin | M9: whistberlin.xlsx
A10: 8 | B10: x | C10: 43407 | D10: -92 | E10: -84 | F10: -180 | G10: 356 | H10: =sum(D10+F10+E10+G10) -> 0 | I10: 51 | L10: Thomas | M10: Whist Thomas.xlsx
A11: 9 | B11: x | C11: 43491 | D11: -132 | E11: -160 | F11: 282 | G11: 10 | H11: =sum(D11+F11+E11+G11) -> 0 | I11: 41 | L11: Peter, Lyngby | M11: Whist – 26-01-2019 | N11: Foto – bl.a. af Peter, der skærer en lækker steg. Og af regnskabsbogen.
A12: 10 | B12: x | C12: 43644 | D12: 320 | E12: -64 | F12: -152 | G12: -104 | H12: =sum(D12+F12+E12+G12) -> 0 | I12: 32 | L12: Peter, Lyngby (Pool) | M12: Whist Ongoing.xlsx | N12: Foto bl.a. af poolen
A13: 11 | B13: x | C13: 43798 | D13: 226 | E13: -222 | F13: 6 | G13: -10 | H13: =sum(D13+F13+E13+G13) -> 0 | I13: 26 | L13: Dyrehaven, Vesterbro | M13: Whist Ongoing.xlsx | N13: Foto og videoer (+ foto i WhatsApp-tråden)
A14: 12a | B14: x | C14: 43882 | D14: 0 | E14: -8 | F14: 48 | G14: -40 | H14: =sum(D14+F14+E14+G14) -> 0 | I14: 8 | L14: Peter, Løkken | M14: Whist Ongoing.xlsx | N14: På samme ark som 12b (12a er fra færgen)
A15: 12b | B15: x | C15: 43882 | D15: 104 | E15: -88 | F15: -32 | G15: 16 | H15: =sum(D15+F15+E15+G15) -> 0 | I15: 27 | L15: Peter, Løkken | M15: Whist Ongoing.xlsx
A16: 13 | B16: x | C16: 43883 | D16: 178 | E16: -134 | F16: 142 | G16: -186 | H16: =sum(D16+F16+E16+G16) -> 0 | I16: 31 | L16: Peter, Løkken | M16: Whist Ongoing.xlsx
A17: 14 | B17: x | C17: 44106 | D17: -72 | E17: -40 | F17: 224 | G17: -112 | H17: =sum(D17+F17+E17+G17) -> 0 | I17: 27 | L17: Christian, Østerbro | M17: Whist Ongoing.xlsx
A18: 15 | B18: x | C18: 44365 | D18: 8 | E18: 128 | F18: -176 | G18: 40 | H18: =sum(D18+F18+E18+G18) -> 0 | I18: 18 | L18: Thomas, Valby | M18: Whist Ongoing.xlsx
A19: 16 | B19: x | C19: 44518 | D19: -300 | E19: -20 | F19: 12 | G19: 308 | H19: =sum(D19+F19+E19+G19) -> 0 | I19: 27 | L19: Stempel, Vesterbro | M19: Whist Ongoing.xlsx
A20: 17 | B20: x | C20: 44617 | D20: 96 | E20: -304 | F20: 368 | G20: -160 | H20: =sum(D20+F20+E20+G20) -> 0 | I20: 25 | L20: Peter, Løkken | M20: whistløkken2022.xlsx
A21: 18 | B21: x | C21: 44618 | D21: 286 | E21: -282 | F21: 30 | G21: -34 | H21: =sum(D21+F21+E21+G21) -> 0 | I21: 40 | L21: Peter, Løkken | M21: whistløkken2022.xlsx
A22: 19 | B22: x | C22: 44939 | D22: 104 | E22: -248 | F22: 68 | G22: 76 | H22: =sum(D22+F22+E22+G22) -> 0 | I22: 8 | L22: Janus, Berlin | M22: whistberlin2023.xlsx | N22: Færgen mod Tyskland
A23: 20 | B23: x | C23: 44940 | D23: 312 | E23: -100 | F23: -136 | G23: -76 | H23: =sum(D23+F23+E23+G23) -> 0 | I23: 30 | L23: Janus, Berlin | M23: whistberlin2023.xlsx | N23: Lørdag
A24: 21 | C24: 45085 | D24: -80 | E24: -168 | F24: 88 | G24: 160 | H24: =sum(D24+F24+E24+G24) -> 0 | I24: 22 | L24: Kayak Bar | M24: whistkajakbar2023.xlsx | N24: På Kayak Bar
A25: 22 | C25: 45199 | D25: -326 | E25: -330 | F25: 282 | G25: 374 | H25: =sum(D25+F25+E25+G25) -> 0 | I25: 39 | L25: Peter, Lyngby | M25: whistLyngby2023 | N25: Delt over i tre afdelinger
A26: 23 | C26: 45470 | D26: -294 | E26: -286 | F26: 366 | G26: 214 | H26: =sum(D26+F26+E26+G26) -> 0 | I26: 19 | L26: Kayak Bar
A27: 24 | C27: 45510 | D27: 366 | E27: -858 | F27: 2 | G27: 490 | H27: =sum(D27+F27+E27+G27) -> 0 | I27: 17 | L27: Thomas, Valby
A28: 25 | C28: 45625 | D28: 224 | E28: 168 | F28: -56 | G28: -336 | H28: =sum(D28+F28+E28+G28) -> 0 | I28: 20 | L28: Janus, Berlin
A29: 26 | C29: 45626 | D29: 184 | E29: -32 | F29: -96 | G29: -56 | H29: =sum(D29+F29+E29+G29) -> 0 | I29: 29 | L29: Janus, Berlin
A30: 27 | C30: 45744 | D30: -12 | E30: -76 | F30: 164 | G30: -72 | H30: =sum(D30+F30+E30+G30) -> 4 | L30: Dyrhaven
A31: 28 | C31: 45822 | D31: 285 | E31: -123 | F31: 39 | G31: -201 | H31: =sum(D31+F31+E31+G31) -> 0 | L31: Peter (efter skydebanen)
C33: Minimum | D33: =MIN(D3:D32) -> -398 | E33: =MIN(E3:E32) -> -872 | F33: =MIN(F3:F32) -> -180 | G33: =MIN(G3:G32) -> -404 | I33: =MIN(I3:I32) -> 8
C34: Gennemsnit | D34: =AVERAGE(D3:D32) -> 43.821429 | E34: =AVERAGE(E3:E32) -> -153.32143 | F34: =AVERAGE(F3:F32) -> 107.39286 | G34: =AVERAGE(G3:G32) -> -1.4642857 | I34: =AVERAGE(I3:I32) -> 26.807692
C35: Maksimum | D35: =MAX(D3:D32) -> 544 | E35: =MAX(E3:E32) -> 234 | F35: =MAX(F3:F32) -> 554 | G35: =MAX(G3:G32) -> 490 | I35: =MAX(I3:I32) -> 51
D36: =sum(D3:D32) -> 1227 | E36: =sum(E3:E32) -> -4293 | F36: =sum(F3:F32) -> 3007 | G36: =sum(G3:G32) -> -41 | I36: =sum(I3:I32) -> 697
A37: KUN fra runde 8
C38: Minimum | D38: =MIN(D10:D27) -> -326 | E38: =MIN(E10:E27) -> -858 | F38: =MIN(F10:F27) -> -180 | G38: =MIN(G10:G27) -> -186
C39: Gennemsnit | D39: =AVERAGE(D10:D27) -> 39.111111 | E39: =AVERAGE(E10:E27) -> -181.55556 | F39: =AVERAGE(F10:F27) -> 69 | G39: =AVERAGE(G10:G27) -> 73.444444
C40: Maksimum | D40: =MAX(D10:D27) -> 366 | E40: =MAX(E10:E27) -> 128 | F40: =MAX(F10:F27) -> 368 | G40: =MAX(G10:G27) -> 490
D41: =sum(D10:D27) -> 704 | E41: =sum(E10:E27) -> -3268 | F41: =sum(F10:F27) -> 1242 | G41: =sum(G10:G27) -> 1322

Sheet STATISTIK_chipleader
A1: Rang | B1: Thomas | C1: Peter | D1: Janus | E1: Christian | G1: ='00_Regnskab_01'!D2 -> Thomas | H1: ='00_Regnskab_01'!E2 -> Peter | I1: ='00_Regnskab_01'!F2 -> Janus | J1: ='00_Regnskab_01'!G2 -> Christian | K1: Thomas placerin | L1: Peters | M1: Janus | N1: Christian'
A2: 1 | B2: =COUNTIF(K2:K31, 1) -> 11 | C2: =COUNTIF(L2:L31, 1) -> 2 | D2: =COUNTIF(M2:M31, 1) -> 9 | E2: =COUNTIF(N2:N31, 1) -> 7 | G2: ='00_Regnskab_01'!D3 -> -230 | H2: ='00_Regnskab_01'!E3 -> -166 | I2: ='00_Regnskab_01'!F3 -> 370 | J2: ='00_Regnskab_01'!G3 -> 8 | K2: =_xlfn.RANK.EQ(G2, G2:J2, FALSE) -> 4 | L2: =_xlfn.RANK.EQ(H2, G2:J2, FALSE) -> 3 | M2: =_xlfn.RANK.EQ(I2, G2:J2, FALSE) -> 1 | N2: =_xlfn.RANK.EQ(J2, G2:J2, FALSE) -> 2
A3: 2 | B3: =COUNTIF(K2:K31, 2) -> 4 | C3: =COUNTIF(L2:L31, 2) -> 6 | D3: =COUNTIF(M2:M31, 2) -> 10 | E3: =COUNTIF(N3:N32, 2) -> 6 | G3: ='00_Regnskab_01'!D4 -> 544 | H3: ='00_Regnskab_01'!E4 -> -872 | I3: ='00_Regnskab_01'!F4 -> 472 | J3: ='00_Regnskab_01'!G4 -> -258 | K3: =_xlfn.RANK.EQ(G3, G3:J3, FALSE) -> 1 | L3: =_xlfn.RANK.EQ(H3, G3:J3, FALSE) -> 4 | M3: =_xlfn.RANK.EQ(I3, G3:J3, FALSE) -> 2 | N3: =_xlfn.RANK.EQ(J3, G3:J3, FALSE) -> 3
A4: 3 | B4: =COUNTIF(K2:K31, 3) -> 8 | C4: =COUNTIF(L2:L31, 3) -> 8 | D4: =COUNTIF(M2:M31, 3) -> 4 | E4: =COUNTIF(N4:N33, 3) -> 9 | G4: ='00_Regnskab_01'!D5 -> 54 | H4: ='00_Regnskab_01'!E5 -> 234 | I4: ='00_Regnskab_01'!F5 -> 148 | J4: ='00_Regnskab_01'!G5 -> -404 | K4: =_xlfn.RANK.EQ(G4, G4:J4, FALSE) -> 3 | L4: =_xlfn.RANK.EQ(H4, G4:J4, FALSE) -> 1 | M4: =_xlfn.RANK.EQ(I4, G4:J4, FALSE) -> 2 | N4: =_xlfn.RANK.EQ(J4, G4:J4, FALSE) -> 4
A5: 4 | B5: =COUNTIF(K2:K31, 4) -> 5 | C5: =COUNTIF(L2:L31, 4) -> 12 | D5: =COUNTIF(M2:M31, 4) -> 5 | E5: =COUNTIF(N5:N34, 4) -> 5 | G5: ='00_Regnskab_01'!D6 -> -72 | H5: ='00_Regnskab_01'!E6 -> -256 | I5: ='00_Regnskab_01'!F6 -> 138 | J5: ='00_Regnskab_01'!G6 -> 186 | K5: =_xlfn.RANK.EQ(G5, G5:J5, FALSE) -> 3 | L5: =_xlfn.RANK.EQ(H5, G5:J5, FALSE) -> 4 | M5: =_xlfn.RANK.EQ(I5, G5:J5, FALSE) -> 2 | N5: =_xlfn.RANK.EQ(J5, G5:J5, FALSE) -> 1
G6: ='00_Regnskab_01'!D7 | H6: ='00_Regnskab_01'!E7 | I6: ='00_Regnskab_01'!F7 | J6: ='00_Regnskab_01'!G7 | K6: =_xlfn.RANK.EQ(G6, G6:J6, FALSE) -> #N/A | L6: =_xlfn.RANK.EQ(H6, G6:J6, FALSE) -> #N/A | M6: =_xlfn.RANK.EQ(I6, G6:J6, FALSE) -> #N/A | N6: =_xlfn.RANK.EQ(J6, G6:J6, FALSE) -> #N/A
A7: Gennemsnit | B7: =(1*B2 + 2*B3 + 3*B4 + 4*B5) / SUM(B2:B5) -> 2.25 | C7: =(1*C2 + 2*C3 + 3*C4 + 4*C5) / SUM(C2:C5) -> 3.0714286 | D7: =(1*D2 + 2*D3 + 3*D4 + 4*D5) / SUM(D2:D5) -> 2.1785714 | E7: =(1*E2 + 2*E3 + 3*E4 + 4*E5) / SUM(E2:E5) -> 2.4444444 | G7: ='00_Regnskab_01'!D8 -> -398 | H7: ='00_Regnskab_01'!E8 -> 106 | I7: ='00_Regnskab_01'!F8 -> 554 | J7: ='00_Regnskab_01'!G8 -> -262 | K7: =_xlfn.RANK.EQ(G7, G7:J7, FALSE) -> 4 | L7: =_xlfn.RANK.EQ(H7, G7:J7, FALSE) -> 2 | M7: =_xlfn.RANK.EQ(I7, G7:J7, FALSE) -> 1 | N7: =_xlfn.RANK.EQ(J7, G7:J7, FALSE) -> 3
G8: ='00_Regnskab_01'!D9 -> -56 | H8: ='00_Regnskab_01'!E9 -> -8 | I8: ='00_Regnskab_01'!F9 -> 32 | J8: ='00_Regnskab_01'!G9 -> 32 | K8: =_xlfn.RANK.EQ(G8, G8:J8, FALSE) -> 4 | L8: =_xlfn.RANK.EQ(H8, G8:J8, FALSE) -> 3 | M8: =_xlfn.RANK.EQ(I8, G8:J8, FALSE) -> 1 | N8: =_xlfn.RANK.EQ(J8, G8:J8, FALSE) -> 1
A9: PROCENT | G9: ='00_Regnskab_01'!D10 -> -92 | H9: ='00_Regnskab_01'!E10 -> -84 | I9: ='00_Regnskab_01'!F10 -> -180 | J9: ='00_Regnskab_01'!G10 -> 356 | K9: =_xlfn.RANK.EQ(G9, G9:J9, FALSE) -> 3 | L9: =_xlfn.RANK.EQ(H9, G9:J9, FALSE) -> 2 | M9: =_xlfn.RANK.EQ(I9, G9:J9, FALSE) -> 4 | N9: =_xlfn.RANK.EQ(J9, G9:J9, FALSE) -> 1
A10: 1 | B10: =B2 / SUM(B$2:B$5) -> 0.39285714 | C10: =C2 / SUM(C$2:C$5) -> 0.071428571 | D10: =D2 / SUM(D$2:D$5) -> 0.32142857 | E10: =E2 / SUM(E$2:E$5) -> 0.25925926 | G10: ='00_Regnskab_01'!D11 -> -132 | H10: ='00_Regnskab_01'!E11 -> -160 | I10: ='00_Regnskab_01'!F11 -> 282 | J10: ='00_Regnskab_01'!G11 -> 10 | K10: =_xlfn.RANK.EQ(G10, G10:J10, FALSE) -> 3 | L10: =_xlfn.RANK.EQ(H10, G10:J10, FALSE) -> 4 | M10: =_xlfn.RANK.EQ(I10, G10:J10, FALSE) -> 1 | N10: =_xlfn.RANK.EQ(J10, G10:J10, FALSE) -> 2
A11: 2 | B11: =B3 / SUM(B$2:B$5) -> 0.14285714 | C11: =C3 / SUM(C$2:C$5) -> 0.21428571 | D11: =D3 / SUM(D$2:D$5) -> 0.35714286 | E11: =E3 / SUM(E$2:E$5) -> 0.22222222 | G11: ='00_Regnskab_01'!D12 -> 320 | H11: ='00_Regnskab_01'!E12 -> -64 | I11: ='00_Regnskab_01'!F12 -> -152 | J11: ='00_Regnskab_01'!G12 -> -104 | K11: =_xlfn.RANK.EQ(G11, G11:J11, FALSE) -> 1 | L11: =_xlfn.RANK.EQ(H11, G11:J11, FALSE) -> 2 | M11: =_xlfn.RANK.EQ(I11, G11:J11, FALSE) -> 4 | N11: =_xlfn.RANK.EQ(J11, G11:J11, FALSE) -> 3
A12: 3 | B12: =B4 / SUM(B$2:B$5) -> 0.28571429 | C12: =C4 / SUM(C$2:C$5) -> 0.28571429 | D12: =D4 / SUM(D$2:D$5) -> 0.14285714 | E12: =E4 / SUM(E$2:E$5) -> 0.33333333 | G12: ='00_Regnskab_01'!D13 -> 226 | H12: ='00_Regnskab_01'!E13 -> -222 | I12: ='00_Regnskab_01'!F13 -> 6 | J12: ='00_Regnskab_01'!G13 -> -10 | K12: =_xlfn.RANK.EQ(G12, G12:J12, FALSE) -> 1 | L12: =_xlfn.RANK.EQ(H12, G12:J12, FALSE) -> 4 | M12: =_xlfn.RANK.EQ(I12, G12:J12, FALSE) -> 2 | N12: =_xlfn.RANK.EQ(J12, G12:J12, FALSE) -> 3
A13: 4 | B13: =B5 / SUM(B$2:B$5) -> 0.17857143 | C13: =C5 / SUM(C$2:C$5) -> 0.42857143 | D13: =D5 / SUM(D$2:D$5) -> 0.17857143 | E13: =E5 / SUM(E$2:E$5) -> 0.18518519 | G13: ='00_Regnskab_01'!D14 -> 0 | H13: ='00_Regnskab_01'!E14 -> -8 | I13: ='00_Regnskab_01'!F14 -> 48 | J13: ='00_Regnskab_01'!G14 -> -40 | K13: =_xlfn.RANK.EQ(G13, G13:J13, FALSE) -> 2 | L13: =_xlfn.RANK.EQ(H13, G13:J13, FALSE) -> 3 | M13: =_xlfn.RANK.EQ(I13, G13:J13, FALSE) -> 1 | N13: =_xlfn.RANK.EQ(J13, G13:J13, FALSE) -> 4
G14: ='00_Regnskab_01'!D15 -> 104 | H14: ='00_Regnskab_01'!E15 -> -88 | I14: ='00_Regnskab_01'!F15 -> -32 | J14: ='00_Regnskab_01'!G15 -> 16 | K14: =_xlfn.RANK.EQ(G14, G14:J14, FALSE) -> 1 | L14: =_xlfn.RANK.EQ(H14, G14:J14, FALSE) -> 4 | M14: =_xlfn.RANK.EQ(I14, G14:J14, FALSE) -> 3 | N14: =_xlfn.RANK.EQ(J14, G14:J14, FALSE) -> 2
G15: ='00_Regnskab_01'!D16 -> 178 | H15: ='00_Regnskab_01'!E16 -> -134 | I15: ='00_Regnskab_01'!F16 -> 142 | J15: ='00_Regnskab_01'!G16 -> -186 | K15: =_xlfn.RANK.EQ(G15, G15:J15, FALSE) -> 1 | L15: =_xlfn.RANK.EQ(H15, G15:J15, FALSE) -> 3 | M15: =_xlfn.RANK.EQ(I15, G15:J15, FALSE) -> 2 | N15: =_xlfn.RANK.EQ(J15, G15:J15, FALSE) -> 4
G16: ='00_Regnskab_01'!D17 -> -72 | H16: ='00_Regnskab_01'!E17 -> -40 | I16: ='00_Regnskab_01'!F17 -> 224 | J16: ='00_Regnskab_01'!G17 -> -112 | K16: =_xlfn.RANK.EQ(G16, G16:J16, FALSE) -> 3 | L16: =_xlfn.RANK.EQ(H16, G16:J16, FALSE) -> 2 | M16: =_xlfn.RANK.EQ(I16, G16:J16, FALSE) -> 1 | N16: =_xlfn.RANK.EQ(J16, G16:J16, FALSE) -> 4
G17: ='00_Regnskab_01'!D18 -> 8 | H17: ='00_Regnskab_01'!E18 -> 128 | I17: ='00_Regnskab_01'!F18 -> -176 | J17: ='00_Regnskab_01'!G18 -> 40 | K17: =_xlfn.RANK.EQ(G17, G17:J17, FALSE) -> 3 | L17: =_xlfn.RANK.EQ(H17, G17:J17, FALSE) -> 1 | M17: =_xlfn.RANK.EQ(I17, G17:J17, FALSE) -> 4 | N17: =_xlfn.RANK.EQ(J17, G17:J17, FALSE) -> 2
G18: ='00_Regnskab_01'!D19 -> -300 | H18: ='00_Regnskab_01'!E19 -> -20 | I18: ='00_Regnskab_01'!F19 -> 12 | J18: ='00_Regnskab_01'!G19 -> 308 | K18: =_xlfn.RANK.EQ(G18, G18:J18, FALSE) -> 4 | L18: =_xlfn.RANK.EQ(H18, G18:J18, FALSE) -> 3 | M18: =_xlfn.RANK.EQ(I18, G18:J18, FALSE) -> 2 | N18: =_xlfn.RANK.EQ(J18, G18:J18, FALSE) -> 1
G19: ='00_Regnskab_01'!D20 -> 96 | H19: ='00_Regnskab_01'!E20 -> -304 | I19: ='00_Regnskab_01'!F20 -> 368 | J19: ='00_Regnskab_01'!G20 -> -160 | K19: =_xlfn.RANK.EQ(G19, G19:J19, FALSE) -> 2 | L19: =_xlfn.RANK.EQ(H19, G19:J19, FALSE) -> 4 | M19: =_xlfn.RANK.EQ(I19, G19:J19, FALSE) -> 1 | N19: =_xlfn.RANK.EQ(J19, G19:J19, FALSE) -> 3
G20: ='00_Regnskab_01'!D21 -> 286 | H20: ='00_Regnskab_01'!E21 -> -282 | I20: ='00_Regnskab_01'!F21 -> 30 | J20: ='00_Regnskab_01'!G21 -> -34 | K20: =_xlfn.RANK.EQ(G20, G20:J20, FALSE) -> 1 | L20: =_xlfn.RANK.EQ(H20, G20:J20, FALSE) -> 4 | M20: =_xlfn.RANK.EQ(I20, G20:J20, FALSE) -> 2 | N20: =_xlfn.RANK.EQ(J20, G20:J20, FALSE) -> 3
G21: ='00_Regnskab_01'!D22 -> 104 | H21: ='00_Regnskab_01'!E22 -> -248 | I21: ='00_Regnskab_01'!F22 -> 68 | J21: ='00_Regnskab_01'!G22 -> 76 | K21: =_xlfn.RANK.EQ(G21, G21:J21, FALSE) -> 1 | L21: =_xlfn.RANK.EQ(H21, G21:J21, FALSE) -> 4 | M21: =_xlfn.RANK.EQ(I21, G21:J21, FALSE) -> 3 | N21: =_xlfn.RANK.EQ(J21, G21:J21, FALSE) -> 2
G22: ='00_Regnskab_01'!D23 -> 312 | H22: ='00_Regnskab_01'!E23 -> -100 | I22: ='00_Regnskab_01'!F23 -> -136 | J22: ='00_Regnskab_01'!G23 -> -76 | K22: =_xlfn.RANK.EQ(G22, G22:J22, FALSE) -> 1 | L22: =_xlfn.RANK.EQ(H22, G22:J22, FALSE) -> 3 | M22: =_xlfn.RANK.EQ(I22, G22:J22, FALSE) -> 4 | N22: =_xlfn.RANK.EQ(J22, G22:J22, FALSE) -> 2
G23: ='00_Regnskab_01'!D24 -> -80 | H23: ='00_Regnskab_01'!E24 -> -168 | I23: ='00_Regnskab_01'!F24 -> 88 | J23: ='00_Regnskab_01'!G24 -> 160 | K23: =_xlfn.RANK.EQ(G23, G23:J23, FALSE) -> 3 | L23: =_xlfn.RANK.EQ(H23, G23:J23, FALSE) -> 4 | M23: =_xlfn.RANK.EQ(I23, G23:J23, FALSE) -> 2 | N23: =_xlfn.RANK.EQ(J23, G23:J23, FALSE) -> 1
G24: ='00_Regnskab_01'!D25 -> -326 | H24: ='00_Regnskab_01'!E25 -> -330 | I24: ='00_Regnskab_01'!F25 -> 282 | J24: ='00_Regnskab_01'!G25 -> 374 | K24: =_xlfn.RANK.EQ(G24, G24:J24, FALSE) -> 3 | L24: =_xlfn.RANK.EQ(H24, G24:J24, FALSE) -> 4 | M24: =_xlfn.RANK.EQ(I24, G24:J24, FALSE) -> 2 | N24: =_xlfn.RANK.EQ(J24, G24:J24, FALSE) -> 1
G25: ='00_Regnskab_01'!D26 -> -294 | H25: ='00_Regnskab_01'!E26 -> -286 | I25: ='00_Regnskab_01'!F26 -> 366 | J25: ='00_Regnskab_01'!G26 -> 214 | K25: =_xlfn.RANK.EQ(G25, G25:J25, FALSE) -> 4 | L25: =_xlfn.RANK.EQ(H25, G25:J25, FALSE) -> 3 | M25: =_xlfn.RANK.EQ(I25, G25:J25, FALSE) -> 1 | N25: =_xlfn.RANK.EQ(J25, G25:J25, FALSE) -> 2
... G36: ='00_Regnskab_01'!D37 | H36: ='00_Regnskab_01'!E37 | I36: ='00_Regnskab_01'!F37 | J36: ='00_Regnskab_01'!G37 | K36: =_xlfn.RANK.EQ(G36, G36:J36, FALSE) -> #N/A | L36: =_xlfn.RANK.EQ(H36, G36:J36, FALSE) -> #N/A | M36: =_xlfn.RANK.EQ(I36, G36:J36, FALSE) -> #N/A | N36: =_xlfn.RANK.EQ(J36, G36:J36, FALSE) -> #N/A

Sheet d_udvikling
C1: Thomas | D1: Janus | E1: Peter | F1: Christian | H1: # | J1: Thomas | K1: Janus | L1: Peter | M1: Christian
A2: 1 | B2: 42542 | C2: -230 | D2: 370 | E2: -166 | F2: 8 | H2: =A2 -> 1 | I2: =B2 -> 42542 | J2: =C2 -> -230 | K2: =D2 -> 370 | L2: =E2 -> -166 | M2: =F2 -> 8
A3: 2 | B3: 42637 | C3: 544 | D3: 472 | E3: -872 | F3: -258 | H3: =A3 -> 2 | I3: =B3 -> 42637 | J3: =sum(C3+J2) -> 314 | K3: =sum(D3+K2) -> 842 | L3: =sum(E3+L2) -> -1038 | M3: =sum(F3+M2) -> -250
A4: 3 | B4: 42791 | C4: 54 | D4: 148 | E4: 234 | F4: -404 | H4: =A4 -> 3 | I4: =B4 -> 42791 | J4: =sum(C4+J3) -> 368 | K4: =sum(D4+K3) -> 990 | L4: =sum(E4+L3) -> -804 | M4: =sum(F4+M3) -> -654
A5: 4 | B5: ? | C5: -72 | D5: 138 | E5: -256 | F5: 186 | H5: =A5 -> 4 | I5: 42887 | J5: =sum(C5+J4) -> 296 | K5: =sum(D5+K4) -> 1128 | L5: =sum(E5+L4) -> -1060 | M5: =sum(F5+M4) -> -468
A6: 6 | B6: 43001 | C6: -398 | D6: 554 | E6: 106 | F6: -262 | H6: =A6 -> 6 | I6: =B6 -> 43001 | J6: =sum(C6+J5) -> -102 | K6: =sum(D6+K5) -> 1682 | L6: =sum(E6+L5) -> -954 | M6: =sum(F6+M5) -> -730
A7: 7 | B7: 43002 | C7: -56 | D7: 32 | E7: -8 | F7: 32 | H7: =A7 -> 7 | I7: =B7 -> 43002 | J7: =sum(C7+J6) -> -158 | K7: =sum(D7+K6) -> 1714 | L7: =sum(E7+L6) -> -962 | M7: =sum(F7+M6) -> -698
A8: 8 | B8: 43407 | C8: -92 | D8: -180 | E8: -84 | F8: 356 | H8: =A8 -> 8 | I8: =B8 -> 43407 | J8: =sum(C8+J7) -> -250 | K8: =sum(D8+K7) -> 1534 | L8: =sum(E8+L7) -> -1046 | M8: =sum(F8+M7) -> -342
A9: 9 | B9: 43491 | C9: -132 | D9: 282 | E9: -160 | F9: 10 | H9: =A9 -> 9 | I9: =B9 -> 43491 | J9: =sum(C9+J8) -> -382 | K9: =sum(D9+K8) -> 1816 | L9: =sum(E9+L8) -> -1206 | M9: =sum(F9+M8) -> -332
A10: 10 | B10: 43644 | C10: 320 | D10: -152 | E10: -64 | F10: -104 | H10: =A10 -> 10 | I10: =B10 -> 43644 | J10: =sum(C10+J9) -> -62 | K10: =sum(D10+K9) -> 1664 | L10: =sum(E10+L9) -> -1270 | M10: =sum(F10+M9) -> -436
A11: 11 | B11: 43798 | C11: 226 | D11: 6 | E11: -222 | F11: -10 | H11: =A11 -> 11 | I11: =B11 -> 43798 | J11: =sum(C11+J10) -> 164 | K11: =sum(D11+K10) -> 1670 | L11: =sum(E11+L10) -> -1492 | M11: =sum(F11+M10) -> -446
A12: 12a | B12: 43882 | C12: 0 | D12: 48 | E12: -8 | F12: -40 | H12: =A12 -> 12a | I12: =B12 -> 43882 | J12: =sum(C12+J11) -> 164 | K12: =sum(D12+K11) -> 1718 | L12: =sum(E12+L11) -> -1500 | M12: =sum(F12+M11) -> -486
A13: 12b | B13: 43882 | C13: 104 | D13: -32 | E13: -88 | F13: 16 | H13: =A13 -> 12b | I13: =B13 -> 43882 | J13: =sum(C13+J12) -> 268 | K13: =sum(D13+K12) -> 1686 | L13: =sum(E13+L12) -> -1588 | M13: =sum(F13+M12) -> -470
A14: 13 | B14: 43883 | C14: 178 | D14: 142 | E14: -134 | F14: -186 | H14: =A14 -> 13 | I14: =B14 -> 43883 | J14: =sum(C14+J13) -> 446 | K14: =sum(D14+K13) -> 1828 | L14: =sum(E14+L13) -> -1722 | M14: =sum(F14+M13) -> -656
A15: 14 | B15: 44106 | C15: -72 | D15: 224 | E15: -40 | F15: -112 | H15: =A15 -> 14 | I15: =B15 -> 44106 | J15: =sum(C15+J14) -> 374 | K15: =sum(D15+K14) -> 2052 | L15: =sum(E15+L14) -> -1762 | M15: =sum(F15+M14) -> -768
A16: 15 | B16: 44365 | C16: 8 | D16: -176 | E16: 128 | F16: 40 | H16: =A16 -> 15 | I16: =B16 -> 44365 | J16: =sum(C16+J15) -> 382 | K16: =sum(D16+K15) -> 1876 | L16: =sum(E16+L15) -> -1634 | M16: =sum(F16+M15) -> -728
A17: 16 | B17: 44518 | C17: -300 | D17: 12 | E17: -20 | F17: 308 | H17: =A17 -> 16 | I17: =B17 -> 44518 | J17: =sum(C17+J16) -> 82 | K17: =sum(D17+K16) -> 1888 | L17: =sum(E17+L16) -> -1654 | M17: =sum(F17+M16) -> -420
A18: 17 | B18: 44617 | C18: 96 | D18: 368 | E18: -304 | F18: -160 | H18: =A18 -> 17 | I18: =B18 -> 44617 | J18: =sum(C18+J17) -> 178 | K18: =sum(D18+K17) -> 2256 | L18: =sum(E18+L17) -> -1958 | M18: =sum(F18+M17) -> -580
A19: 18 | B19: 44618 | C19: 286 | D19: 30 | E19: -34 | F19: -282 | H19: =A19 -> 18 | I19: =B19 -> 44618 | J19: =sum(C19+J18) -> 464 | K19: =sum(D19+K18) -> 2286 | L19: =sum(E19+L18) -> -1992 | M19: =sum(F19+M18) -> -862
A20: 19 | B20: 44939 | C20: 26 | D20: 86 | E20: 102 | F20: -214 | H20: =A20 -> 19 | I20: =B20 -> 44939 | J20: =sum(C20+J19) -> 490 | K20: =sum(D20+K19) -> 2372 | L20: =sum(E20+L19) -> -1890 | M20: =sum(F20+M19) -> -1076
A21: 20 | B21: 44939 | C21: 104 | D21: 68 | E21: -248 | F21: 76 | H21: =A21 -> 20 | I21: =B21 -> 44939 | J21: =sum(C21+J20) -> 594 | K21: =sum(D21+K20) -> 2440 | L21: =sum(E21+L20) -> -2138 | M21: =sum(F21+M20) -> -1000
A22: 21 | B22: 44940 | C22: 312 | D22: -136 | E22: -100 | F22: -76 | H22: =A22 -> 21 | I22: =B22 -> 44940 | J22: =sum(C22+J21) -> 906 | K22: =sum(D22+K21) -> 2304 | L22: =sum(E22+L21) -> -2238 | M22: =sum(F22+M21) -> -1076
A23: 22 | B23: 45085 | C23: -80 | D23: 88 | E23: -168 | F23: 160 | H23: =A23 -> 22 | I23: =B23 -> 45085 | J23: =sum(C23+J22) -> 826 | K23: =sum(D23+K22) -> 2392 | L23: =sum(E23+L22) -> -2406 | M23: =sum(F23+M22) -> -916
A24: 23 | B24: 31/09/2023 | C24: -22 | D24: 294 | E24: -670 | F24: 398 | H24: 23 | I24: =B24 -> 31/09/2023 | J24: =sum(C24+J23) -> 804 | K24: =sum(D24+K23) -> 2686 | L24: =sum(E24+L23) -> -3076 | M24: =sum(F24+M23) -> -518

Sheet SAMLET_alle regnskab
B1: ='00_Regnskab_01'!A11 -> 9 | C1: ='00_Regnskab_01'!C11 -> 43491 | E1: ='00_Regnskab_01'!L11 -> Peter, Lyngby | T1: due | BB1: test | BC1: DATO
M2: Melding | U2: Vundet / tabt pr. hånd | AB2: MED MELDING | AH2: vundet | AI2: tabt | AK2: VINDERE | AS2: TABERE | AX2: MAKKER | BD2: STREAKS | BE2: WIN / RUNDER | BJ2: LOOSE / RUNDER | BO2: WIN / KR | BT2: LOOSE / KR | BY2: SPILLEDAGE
A3: # | B3: spil | C3: Thomas | D3: Peter | E3: Janus | F3: Christian | G3: Tjek | H3: Melder | I3: Makker | J3: giver | K3: Vindende melding | M3: Antal | N3: Type | O3: Vip | P3: Gode i 3. | Q3: går med | R3: selvmakker | S3: Storslem | U3: =C3 -> Thomas | V3: =D3 -> Peter | W3: =E3 -> Janus | X3: =F3 -> Christian | Z3: Alene? | AB3: =U3 -> Thomas | AC3: =V3 -> Peter | AD3: =W3 -> Janus | AE3: =X3 -> Christian | AH3: =countif(AH4:AH596, ">0") -> 325 | AI3: =countif(AI4:AI596, "<0") -> 215 | AK3: =C3 -> Thomas | AL3: =D3 -> Peter | AM3: =E3 -> Janus | AN3: =F3 -> Christian | AP3: Melding | AQ3: Makker | AS3: =AK3 -> Thomas | AT3: =AL3 -> Peter | AU3: =AM3 -> Janus | AV3: =AN3 -> Christian | AX3: tjek | AY3: =U3 -> Thomas | AZ3: =V3 -> Peter | BA3: =W3 -> Janus | BB3: =X3 -> Christian | BE3: =C3 -> Thomas | BF3: =D3 -> Peter | BG3: =E3 -> Janus | BH3: =F3 -> Christian | BJ3: =C3 -> Thomas | BK3: =D3 -> Peter | BL3: =E3 -> Janus | BM3: =F3 -> Christian | BO3: =C3 -> Thomas | BP3: =D3 -> Peter | BQ3: =E3 -> Janus | BR3: =F3 -> Christian | BT3: =C3 -> Thomas | BU3: =D3 -> Peter | BV3: =E3 -> Janus | BW3: =F3 -> Christian | BY3: (til dropdown)
A4: 1 | C4: ='00_Regnskab_01'!D3 -> -230 | D4: ='00_Regnskab_01'!E3 -> -166 | E4: ='00_Regnskab_01'!F3 -> 370 | F4: ='00_Regnskab_01'!G3 -> 8 | BC4: =OFFSET('00_Regnskab_01'!$A$1,MATCH(A4,'00_Regnskab_01'!$A$1:$A$25)-1,2) -> 42542 | BY4: {=UNIQUE(A4:A596)} -> 1
A5: 2 | C5: ='00_Regnskab_01'!D4 -> 544 | D5: ='00_Regnskab_01'!E4 -> -872 | E5: ='00_Regnskab_01'!F4 -> 472 | F5: ='00_Regnskab_01'!G4 -> -258 | BC5: =OFFSET('00_Regnskab_01'!$A$1,MATCH(A5,'00_Regnskab_01'!$A$1:$A$25)-1,2) -> 42637 | BY5: 2
A6: 3 | C6: ='00_Regnskab_01'!D5 -> 54 | D6: ='00_Regnskab_01'!E5 -> 234 | E6: ='00_Regnskab_01'!F5 -> 148 | F6: ='00_Regnskab_01'!G5 -> -404 | BC6: =OFFSET('00_Regnskab_01'!$A$1,MATCH(A6,'00_Regnskab_01'!$A$1:$A$25)-1,2) -> 42791 | BY6: 3
A7: 4 | C7: ='00_Regnskab_01'!D6 -> -72 | D7: ='00_Regnskab_01'!E6 -> -256 | E7: ='00_Regnskab_01'!F6 -> 138 | F7: ='00_Regnskab_01'!G6 -> 186 | BC7: =OFFSET('00_Regnskab_01'!$A$1,MATCH(A7,'00_Regnskab_01'!$A$1:$A$25)-1,2) -> ? | BY7: 4
A8: 5 | C8: =C7 -> -72 | D8: =D7 -> -256 | E8: =E7 -> 138 | F8: =F7 -> 186 | BC8: =OFFSET('00_Regnskab_01'!$A$1,MATCH(A8,'00_Regnskab_01'!$A$1:$A$25)-1,2) -> 43000 | BY8: 5
A9: 6 | C9: ='00_Regnskab_01'!D8 -> -398 | D9: ='00_Regnskab_01'!E8 -> 106 | E9: ='00_Regnskab_01'!F8 -> 554 | F9: ='00_Regnskab_01'!G8 -> -262 | BC9: =OFFSET('00_Regnskab_01'!$A$1,MATCH(A9,'00_Regnskab_01'!$A$1:$A$25)-1,2) -> 43001 | BY9: 6
A10: 7 | C10: ='00_Regnskab_01'!D9 -> -56 | D10: ='00_Regnskab_01'!E9 -> -8 | E10: ='00_Regnskab_01'!F9 -> 32 | F10: ='00_Regnskab_01'!G9 -> 32 | BC10: =OFFSET('00_Regnskab_01'!$A$1,MATCH(A10,'00_Regnskab_01'!$A$1:$A$25)-1,2) -> 43002 | BY10: 7
A11: 8 | B11: ='08_3-11-2018'!A3 -> 1 | C11: ='08_3-11-2018'!B3 -> 48 | D11: ='08_3-11-2018'!D3 -> -48 | E11: ='08_3-11-2018'!C3 -> 48 | F11: ='08_3-11-2018'!E3 -> -48 | G11: ='08_3-11-2018'!F3 -> 0 | H11: ='08_3-11-2018'!G3 -> Thomas | J11: ='08_3-11-2018'!H3 -> Christian | K11: ='08_3-11-2018'!I3 | U11: =C11 -> 48 | V11: =D11 -> -48 | W11: =E11 -> 48 | X11: =F11 -> -48 | AB11: =IF(AB$3=$H11,U11,"") -> 48 | AC11: =IF(AC$3=$H11,V11,"") | AD11: =IF(AD$3=$H11,W11,"") | AE11: =IF(AE$3=$H11,X11,"") | AH11: =MAXIFS(AB11:AE11,AB11:AE11, ">-1") -> 48 | AI11: =MINIFS(AB11:AE11,AB11:AE11, "<0") -> 0 | AK11: =IF(U11>0,AK$3,"") -> Thomas | AL11: =IF(V11>0,AL$3,"") | AM11: =IF(W11>0,AM$3,"") -> Janus | AN11: =IF(X11>0,AN$3,"") | AO11: =COUNTif(AK11:AN11,">0"&"*") -> 2 | AP11: =H11 -> Thomas | AQ11: =IFERROR(__xludf.DUMMYFUNCTION("IFNA(QUERY(transpose(AY11:BB11),""Select Col1 where Col1 is not null limit 1"",0))"),"Janus") -> Janus | AS11: =IF(AK11=AS$3,"",AS$3) | AT11: =IF(AL11=AT$3,"",AT$3) -> Peter | AU11: =IF(AM11=AU$3,"",AU$3) | AV11: =IF(AN11=AV$3,"",AV$3) -> Christian | AW11: =COUNTif(AS11:AV11,">0"&"*") -> 2 | AX11: =sum(AB11:AE11) -> 48 | AY11: =IFNA(IFS(AY$3=$AP11,"",$AX11=U11,AY$3),"") | AZ11: =IFNA(IFS(AZ$3=$AP11,"",$AX11=V11,AZ$3),"") | BA11: =IFNA(IFS(BA$3=$AP11,"",$AX11=W11,BA$3),"") -> Janus | BB11: =IFNA(IFS(BB$3=$AP11,"",$AX11=X11,BB$3),"") | BC11: =OFFSET('00_Regnskab_01'!$A$1,MATCH(A11,'00_Regnskab_01'!$A$1:$A$25)-1,2) -> 43407 | BE11: =if(U11>0,1+BE10,0) -> 1 | BF11: =if(V11>0,1+BF10,0) -> 0 | BG11: =if(W11>0,1+BG10,0) -> 1 | BH11: =if(X11>0,1+BH10,0) -> 0 | BJ11: =if(U11<0,1+BE10,0) -> 0 | BK11: =if(V11<0,1+BF10,0) -> 1 | BL11: =if(W11<0,1+BG10,0) -> 0 | BM11: =if(X11<0,1+BH10,0) -> 1 | BO11: =if(U11>0,U11+BO10,0) -> 48 | BP11: =if(V11>0,V11+BP10,0) -> 0 | BQ11: =if(W11>0,W11+BQ10,0) -> 48 | BR11: =if(X11>0,X11+BR10,0) -> 0 | BT11: =if(U11<0,U11+BT10,0) -> 0 | BU11: =if(V11<0,V11+BU10,0) -> -48 | BV11: =if(W11<0,W11+BV10,0) -> 0 | BW11: =if(X11<0,X11+BW10,0) -> -48 | BY11: 8
A12: 8 | B12: ='08_3-11-2018'!A4 -> 2 | C12: ='08_3-11-2018'!B4 -> 60 | D12: ='08_3-11-2018'!D4 -> -60 | E12: ='08_3-11-2018'!C4 -> 36 | F12: ='08_3-11-2018'!E4 -> -36 | G12: ='08_3-11-2018'!F4 -> 0 | H12: ='08_3-11-2018'!G4 -> Janus | J12: ='08_3-11-2018'!H4 -> Thomas | K12: ='08_3-11-2018'!I4 | U12: =C12-C11 -> 12 | V12: =D12-D11 -> -12 | W12: =E12-E11 -> -12 | X12: =F12-F11 -> 12 | AB12: =IF(AB$3=$H12,U12,"") | AC12: =IF(AC$3=$H12,V12,"") | AD12: =IF(AD$3=$H12,W12,"") -> -12 | AE12: =IF(AE$3=$H12,X12,"") | AH12: =MAXIFS(AB12:AE12,AB12:AE12, ">-1") -> 0 | AI12: =MINIFS(AB12:AE12,AB12:AE12, "<0") -> -12 | AK12: =IF(U12>0,AK$3,"") -> Thomas | AL12: =IF(V12>0,AL$3,"") | AM12: =IF(W12>0,AM$3,"") | AN12: =IF(X12>0,AN$3,"") -> Christian | AO12: =COUNTif(AK12:AN12,">0"&"*") -> 2 | AP12: =H12 -> Janus | AQ12: =IFERROR(__xludf.DUMMYFUNCTION("IFNA(QUERY(transpose(AY12:BB12),""Select Col1 where Col1 is not null limit 1"",0))"),"Peter") -> Peter | AS12: =IF(AK12=AS$3,"",AS$3) | AT12: =IF(AL12=AT$3,"",AT$3) -> Peter | AU12: =IF(AM12=AU$3,"",AU$3) -> Janus | AV12: =IF(AN12=AV$3,"",AV$3) | AW12: =COUNTif(AS12:AV12,">0"&"*") -> 2 | AX12: =sum(AB12:AE12) -> -12 | AY12: =IFNA(IFS(AY$3=$AP12,"",$AX12=U12,AY$3),"") | AZ12: =IFNA(IFS(AZ$3=$AP12,"",$AX12=V12,AZ$3),"") -> Peter | BA12: =IFNA(IFS(BA$3=$AP12,"",$AX12=W12,BA$3),"") | BB12: =IFNA(IFS(BB$3=$AP12,"",$AX12=X12,BB$3),"") | BC12: =OFFSET('00_Regnskab_01'!$A$1,MATCH(A12,'00_Regnskab_01'!$A$1:$A$25)-1,2) -> 43407 | BE12: =if(U12>0,1+BE11,0) -> 2 | BF12: =if(V12>0,1+BF11,0) -> 0 | BG12: =if(W12>0,1+BG11,0) -> 0 | BH12: =if(X12>0,1+BH11,0) -> 1 | BJ12: =if(U12<0,1+BJ11,0) -> 0 | BK12: =if(V12<0,1+BK11,0) -> 2 | BL12: =if(W12<0,1+BL11,0) -> 1 | BM12: =if(X12<0,1+BM11,0) -> 0 | BO12: =if(U12>0,U12+BO11,0) -> 60 | BP12: =if(V12>0,V12+BP11,0) -> 0 | BQ12: =if(W12>0,W12+BQ11,0) -> 0 | BR12: =if(X12>0,X12+BR11,0) -> 12 | BT12: =if(U12<0,U12+BT11,0) -> 0 | BU12: =if(V12<0,V12+BU11,0) -> -60 | BV12: =if(W12<0,W12+BV11,0) -> -12 | BW12: =if(X12<0,X12+BW11,0) -> 0 | BY12: 9
A13: 8 | B13: ='08_3-11-2018'!A5 -> 3 | C13: ='08_3-11-2018'!B5 -> 76 | D13: ='08_3-11-2018'!D5 -> -108 | E13: ='08_3-11-2018'!C5 -> 52 | F13: ='08_3-11-2018'!E5 -> -20 | G13: ='08_3-11-2018'!F5 -> 0 | H13: ='08_3-11-2018'!G5 -> Peter | J13: ='08_3-11-2018'!H5 -> Janus | K13: ='08_3-11-2018'!I5 | U13: =C13-C12 -> 16 | V13: =D13-D12 -> -48 | W13: =E13-E12 -> 16 | X13: =F13-F12 -> 16 | AB13: =IF(AB$3=$H13,U13,"") | AC13: =IF(AC$3=$H13,V13,"") -> -48 | AD13: =IF(AD$3=$H13,W13,"") | AE13: =IF(AE$3=$H13,X13,"") | AH13: =MAXIFS(AB13:AE13,AB13:AE13, ">-1") -> 0 | AI13: =MINIFS(AB13:AE13,AB13:AE13, "<0") -> -48 | AK13: =IF(U13>0,AK$3,"") -> Thomas | AL13: =IF(V13>0,AL$3,"") | AM13: =IF(W13>0,AM$3,"") -> Janus | AN13: =IF(X13>0,AN$3,"") -> Christian | AO13: =COUNTif(AK13:AN13,">0"&"*") -> 3 | AP13: =H13 -> Peter | AQ13: =IFERROR(__xludf.DUMMYFUNCTION("IFNA(QUERY(transpose(AY13:BB13),""Select Col1 where Col1 is not null limit 1"",0))"),"") | AS13: =IF(AK13=AS$3,"",AS$3) | AT13: =IF(AL13=AT$3,"",AT$3) -> Peter | AU13: =IF(AM13=AU$3,"",AU$3) | AV13: =IF(AN13=AV$3,"",AV$3) | AW13: =COUNTif(AS13:AV13,">0"&"*") -> 1 | AX13: =sum(AB13:AE13) -> -48 | AY13: =IFNA(IFS(AY$3=$AP13,"",$AX13=U13,AY$3),"") | AZ13: =IFNA(IFS(AZ$3=$AP13,"",$AX13=V13,AZ$3),"") | BA13: =IFNA(IFS(BA$3=$AP13,"",$AX13=W13,BA$3),"") | BB13: =IFNA(IFS(BB$3=$AP13,"",$AX13=X13,BB$3),"") | BC13: =OFFSET('00_Regnskab_01'!$A$1,MATCH(A13,'00_Regnskab_01'!$A$1:$A$25)-1,2) -> 43407 | BE13: =if(U13>0,1+BE12,0) -> 3 | BF13: =if(V13>0,1+BF12,0) -> 0 | BG13: =if(W13>0,1+BG12,0) -> 1 | BH13: =if(X13>0,1+BH12,0) -> 2 | BJ13: =if(U13<0,1+BJ12,0) -> 0 | BK13: =if(V13<0,1+BK12,0) -> 3 | BL13: =if(W13<0,1+BL12,0) -> 0 | BM13: =if(X13<0,1+BM12,0) -> 0 | BO13: =if(U13>0,U13+BO12,0) -> 76 | BP13: =if(V13>0,V13+BP12,0) -> 0 | BQ13: =if(W13>0,W13+BQ12,0) -> 16 | BR13: =if(X13>0,X13+BR12,0) -> 28 | BT13: =if(U13<0,U13+BT12,0) -> 0 | BU13: =if(V13<0,V13+BU12,0) -> -108 | BV13: =if(W13<0,W13+BV12,0) -> 0 | BW13: =if(X13<0,X13+BW12,0) -> 0 | BY13: 10
A14: 8 | B14: ='08_3-11-2018'!A6 -> 4 | C14: ='08_3-11-2018'!B6 -> 64 | D14: ='08_3-11-2018'!D6 -> -96 | E14: ='08_3-11-2018'!C6 -> 64 | F14: ='08_3-11-2018'!E6 -> -32 | G14: ='08_3-11-2018'!F6 -> 0 | H14: ='08_3-11-2018'!G6 -> Janus | J14: ='08_3-11-2018'!H6 -> Peter | K14: ='08_3-11-2018'!I6 | U14: =C14-C13 -> -12 | V14: =D14-D13 -> 12 | W14: =E14-E13 -> 12 | X14: =F14-F13 -> -12 | AB14: =IF(AB$3=$H14,U14,"") | AC14: =IF(AC$3=$H14,V14,"") | AD14: =IF(AD$3=$H14,W14,"") -> 12 | AE14: =IF(AE$3=$H14,X14,"") | AH14: =MAXIFS(AB14:AE14,AB14:AE14, ">-1") -> 12 | AI14: =MINIFS(AB14:AE14,AB14:AE14, "<0") -> 0 | AK14: =IF(U14>0,AK$3,"") | AL14: =IF(V14>0,AL$3,"") -> Peter | AM14: =IF(W14>0,AM$3,"") -> Janus | AN14: =IF(X14>0,AN$3,"") | AO14: =COUNTif(AK14:AN14,">0"&"*") -> 2 | AP14: =H14 -> Janus | AQ14: =IFERROR(__xludf.DUMMYFUNCTION("IFNA(QUERY(transpose(AY14:BB14),""Select Col1 where Col1 is not null limit 1"",0))"),"Peter") -> Peter | AS14: =IF(AK14=AS$3,"",AS$3) -> Thomas | AT14: =IF(AL14=AT$3,"",AT$3) | AU14: =IF(AM14=AU$3,"",AU$3) | AV14: =IF(AN14=AV$3,"",AV$3) -> Christian | AW14: =COUNTif(AS14:AV14,">0"&"*") -> 2 | AX14: =sum(AB14:AE14) -> 12 | AY14: =IFNA(IFS(AY$3=$AP14,"",$AX14=U14,AY$3),"") | AZ14: =IFNA(IFS(AZ$3=$AP14,"",$AX14=V14,AZ$3),"") -> Peter | BA14: =IFNA(IFS(BA$3=$AP14,"",$AX14=W14,BA$3),"") | BB14: =IFNA(IFS(BB$3=$AP14,"",$AX14=X14,BB$3),"") | BC14: =OFFSET('00_Regnskab_01'!$A$1,MATCH(A14,'00_Regnskab_01'!$A$1:$A$25)-1,2) -> 43407 | BE14: =if(U14>0,1+BE13,0) -> 0 | BF14: =if(V14>0,1+BF13,0) -> 1 | BG14: =if(W14>0,1+BG13,0) -> 2 | BH14: =if(X14>0,1+BH13,0) -> 0 | BJ14: =if(U14<0,1+BJ13,0) -> 1 | BK14: =if(V14<0,1+BK13,0) -> 0 | BL14: =if(W14<0,1+BL13,0) -> 0 | BM14: =if(X14<0,1+BM13,0) -> 1 | BO14: =if(U14>0,U14+BO13,0) -> 0 | BP14: =if(V14>0,V14+BP13,0) -> 12 | BQ14: =if(W14>0,W14+BQ13,0) -> 28 | BR14: =if(X14>0,X14+BR13,0) -> 0 | BT14: =if(U14<0,U14+BT13,0) -> -12 | BU14: =if(V14<0,V14+BU13,0) -> 0 | BV14: =if(W14<0,W14+BV13,0) -> 0 | BW14: =if(X14<0,X14+BW13,0) -> -12 | BY14: 11
A15: 8 | B15: ='08_3-11-2018'!A7 -> 5 | C15: ='08_3-11-2018'!B7 -> 48 | D15: ='08_3-11-2018'!D7 -> -48 | E15: ='08_3-11-2018'!C7 -> 48 | F15: ='08_3-11-2018'!E7 -> -48 | G15: ='08_3-11-2018'!F7 -> 0 | H15: ='08_3-11-2018'!G7 -> Peter | J15: ='08_3-11-2018'!H7 -> Christian | K15: ='08_3-11-2018'!I7 | U15: =C15-C14 -> -16 | V15: =D15-D14 -> 48 | W15: =E15-E14 -> -16 | X15: =F15-F14 -> -16 | AB15: =IF(AB$3=$H15,U15,"") | AC15: =IF(AC$3=$H15,V15,"") -> 48 | AD15: =IF(AD$3=$H15,W15,"") | AE15: =IF(AE$3=$H15,X15,"") | AH15: =MAXIFS(AB15:AE15,AB15:AE15, ">-1") -> 48 | AI15: =MINIFS(AB15:AE15,AB15:AE15, "<0") -> 0 | AK15: =IF(U15>0,AK$3,"") | AL15: =IF(V15>0,AL$3,"") -> Peter | AM15: =IF(W15>0,AM$3,"") | AN15: =IF(X15>0,AN$3,"") | AO15: =COUNTif(AK15:AN15,">0"&"*") -> 1 | AP15: =H15 -> Peter | AQ15: =IFERROR(__xludf.DUMMYFUNCTION("IFNA(QUERY(transpose(AY15:BB15),""Select Col1 where Col1 is not null limit 1"",0))"),"") | AS15: =IF(AK15=AS$3,"",AS$3) -> Thomas | AT15: =IF(AL15=AT$3,"",AT$3) | AU15: =IF(AM15=AU$3,"",AU$3) -> Janus | AV15: =IF(AN15=AV$3,"",AV$3) -> Christian | AW15: =COUNTif(AS15:AV15,">0"&"*") -> 3 | AX15: =sum(AB15:AE15) -> 48 | AY15: =IFNA(IFS(AY$3=$AP15,"",$AX15=U15,AY$3),"") | AZ15: =IFNA(IFS(AZ$3=$AP15,"",$AX15=V15,AZ$3),"") | BA15: =IFNA(IFS(BA$3=$AP15,"",$AX15=W15,BA$3),"") | BB15: =IFNA(IFS(BB$3=$AP15,"",$AX15=X15,BB$3),"") | BC15: =OFFSET('00_Regnskab_01'!$A$1,MATCH(A15,'00_Regnskab_01'!$A$1:$A$25)-1,2) -> 43407 | BE15: =if(U15>0,1+BE14,0) -> 0 | BF15: =if(V15>0,1+BF14,0) -> 2 | BG15: =if(W15>0,1+BG14,0) -> 0 | BH15: =if(X15>0,1+BH14,0) -> 0 | BJ15: =if(U15<0,1+BJ14,0) -> 2 | BK15: =if(V15<0,1+BK14,0) -> 0 | BL15: =if(W15<0,1+BL14,0) -> 1 | BM15: =if(X15<0,1+BM14,0) -> 2 | BO15: =if(U15>0,U15+BO14,0) -> 0 | BP15: =if(V15>0,V15+BP14,0) -> 60 | BQ15: =if(W15>0,W15+BQ14,0) -> 0 | BR15: =if(X15>0,X15+BR14,0) -> 0 | BT15: =if(U15<0,U15+BT14,0) -> -28 | BU15: =if(V15<0,V15+BU14,0) -> 0 | BV15: =if(W15<0,W15+BV14,0) -> -16 | BW15: =if(X15<0,X15+BW14,0) -> -28 | BY15: 12a
A16: 8 | B16: ='08_3-11-2018'!A8 -> 6 | C16: ='08_3-11-2018'!B8 -> 64 | D16: ='08_3-11-2018'!D8 -> -96 | E16: ='08_3-11-2018'!C8 -> 64 | F16: ='08_3-11-2018'!E8 -> -32 | G16: ='08_3-11-2018'!F8 -> 0 | H16: ='08_3-11-2018'!G8 -> Peter | J16: ='08_3-11-2018'!H8 -> Thomas | K16: ='08_3-11-2018'!I8 | U16: =C16-C15 -> 16 | V16: =D16-D15 -> -48 | W16: =E16-E15 -> 16 | X16: =F16-F15 -> 16 | AB16: =IF(AB$3=$H16,U16,"") | AC16: =IF(AC$3=$H16,V16,"") -> -48 | AD16: =IF(AD$3=$H16,W16,"") | AE16: =IF(AE$3=$H16,X16,"") | AH16: =MAXIFS(AB16:AE16,AB16:AE16, ">-1") -> 0 | AI16: =MINIFS(AB16:AE16,AB16:AE16, "<0") -> -48 | AK16: =IF(U16>0,AK$3,"") -> Thomas | AL16: =IF(V16>0,AL$3,"") | AM16: =IF(W16>0,AM$3,"") -> Janus | AN16: =IF(X16>0,AN$3,"") -> Christian | AO16: =COUNTif(AK16:AN16,">0"&"*") -> 3 | AP16: =H16 -> Peter | AQ16: =IFERROR(__xludf.DUMMYFUNCTION("IFNA(QUERY(transpose(AY16:BB16),""Select Col1 where Col1 is not null limit 1"",0))"),"") | AS16: =IF(AK16=AS$3,"",AS$3) | AT16: =IF(AL16=AT$3,"",AT$3) -> Peter | AU16: =IF(AM16=AU$3,"",AU$3) | AV16: =IF(AN16=AV$3,"",AV$3) | AW16: =COUNTif(AS16:AV16,">0"&"*") -> 1 | AX16: =sum(AB16:AE16) -> -48 | AY16: =IFNA(IFS(AY$3=$AP16,"",$AX16=U16,AY$3),"") | AZ16: =IFNA(IFS(AZ$3=$AP16,"",$AX16=V16,AZ$3),"") | BA16: =IFNA(IFS(BA$3=$AP16,"",$AX16=W16,BA$3),"") | BB16: =IFNA(IFS(BB$3=$AP16,"",$AX16=X16,BB$3),"") | BC16: =OFFSET('00_Regnskab_01'!$A$1,MATCH(A16,'00_Regnskab_01'!$A$1:$A$25)-1,2) -> 43407 | BE16: =if(U16>0,1+BE15,0) -> 1 | BF16: =if(V16>0,1+BF15,0) -> 0 | BG16: =if(W16>0,1+BG15,0) -> 1 | BH16: =if(X16>0,1+BH15,0) -> 1 | BJ16: =if(U16<0,1+BJ15,0) -> 0 | BK16: =if(V16<0,1+BK15,0) -> 1 | BL16: =if(W16<0,1+BL15,0) -> 0 | BM16: =if(X16<0,1+BM15,0) -> 0 | BO16: =if(U16>0,U16+BO15,0) -> 16 | BP16: =if(V16>0,V16+BP15,0) -> 0 | BQ16: =if(W16>0,W16+BQ15,0) -> 16 | BR16: =if(X16>0,X16+BR15,0) -> 16 | BT16: =if(U16<0,U16+BT15,0) -> 0 | BU16: =if(V16<0,V16+BU15,0) -> -48 | BV16: =if(W16<0,W16+BV15,0) -> 0 | BW16: =if(X16<0,X16+BW15,0) -> 0 | BY16: 12b
A17: 8 | B17: ='08_3-11-2018'!A9 -> 7 | C17: ='08_3-11-2018'!B9 -> -96 | D17: ='08_3-11-2018'!D9 -> 64 | E17: ='08_3-11-2018'!C9 -> -96 | F17: ='08_3-11-2018'!E9 -> 128 | G17: ='08_3-11-2018'!F9 -> 0 | H17: ='08_3-11-2018'!G9 -> Thomas | I17: Janus | J17: ='08_3-11-2018'!H9 -> Janus | K17: ='08_3-11-2018'!I9 | U17: =C17-C16 -> -160 | V17: =D17-D16 -> 160 | W17: =E17-E16 -> -160 | X17: =F17-F16 -> 160 | AB17: =IF(AB$3=$H17,U17,"") -> -160 | AC17: =IF(AC$3=$H17,V17,"") | AD17: =IF(AD$3=$H17,W17,"") | AE17: =IF(AE$3=$H17,X17,"") | AH17: =MAXIFS(AB17:AE17,AB17:AE17, ">-1") -> 0 | AI17: =MINIFS(AB17:AE17,AB17:AE17, "<0") -> -160 | AK17: =IF(U17>0,AK$3,"") | AL17: =IF(V17>0,AL$3,"") -> Peter | AM17: =IF(W17>0,AM$3,"") | AN17: =IF(X17>0,AN$3,"") -> Christian | AO17: =COUNTif(AK17:AN17,">0"&"*") -> 2 | AP17: =H17 -> Thomas | AQ17: =IFERROR(__xludf.DUMMYFUNCTION("IFNA(QUERY(transpose(AY17:BB17),""Select Col1 where Col1 is not null limit 1"",0))"),"Janus") -> Janus | AS17: =IF(AK17=AS$3,"",AS$3) -> Thomas | AT17: =IF(AL17=AT$3,"",AT$3) | AU17: =IF(AM17=AU$3,"",AU$3) -> Janus | AV17: =IF(AN17=AV$3,"",AV$3) | AW17: =COUNTif(AS17:AV17,">0"&"*") -> 2 | AX17: =sum(AB17:AE17) -> -160 | AY17: =IFNA(IFS(AY$3=$AP17,"",$AX17=U17,AY$3),"") | AZ17: =IFNA(IFS(AZ$3=$AP17,"",$AX17=V17,AZ$3),"") | BA17: =IFNA(IFS(BA$3=$AP17,"",$AX17=W17,BA$3),"") -> Janus | BB17: =IFNA(IFS(BB$3=$AP17,"",$AX17=X17,BB$3),"") | BC17: =OFFSET('00_Regnskab_01'!$A$1,MATCH(A17,'00_Regnskab_01'!$A$1:$A$25)-1,2) -> 43407 | BE17: =if(U17>0,1+BE16,0) -> 0 | BF17: =if(V17>0,1+BF16,0) -> 1 | BG17: =if(W17>0,1+BG16,0) -> 0 | BH17: =if(X17>0,1+BH16,0) -> 2 | BJ17: =if(U17<0,1+BJ16,0) -> 1 | BK17: =if(V17<0,1+BK16,0) -> 0 | BL17: =if(W17<0,1+BL16,0) -> 1 | BM17: =if(X17<0,1+BM16,0) -> 0 | BO17: =if(U17>0,U17+BO16,0) -> 0 | BP17: =if(V17>0,V17+BP16,0) -> 160 | BQ17: =if(W17>0,W17+BQ16,0) -> 0 | BR17: =if(X17>0,X17+BR16,0) -> 176 | BT17: =if(U17<0,U17+BT16,0) -> -160 | BU17: =if(V17<0,V17+BU16,0) -> 0 | BV17: =if(W17<0,W17+BV16,0) -> -160 | BW17: =if(X17<0,X17+BW16,0) -> 0 | BY17: 13
A18: 8 | B18: ='08_3-11-2018'!A10 -> 8 | C18: ='08_3-11-2018'!B10 -> -84 | D18: ='08_3-11-2018'!D10 -> 76 | E18: ='08_3-11-2018'!C10 -> -108 | F18: ='08_3-11-2018'!E10 -> 116 | G18: ='08_3-11-2018'!F10 -> 0 | H18: ='08_3-11-2018'!G10 -> Christian | J18: ='08_3-11-2018'!H10 -> Peter | K18: ='08_3-11-2018'!I10 | U18: =C18-C17 -> 12 | V18: =D18-D17 -> 12 | W18: =E18-E17 -> -12 | X18: =F18-F17 -> -12 | AB18: =IF(AB$3=$H18,U18,"") | AC18: =IF(AC$3=$H18,V18,"") | AD18: =IF(AD$3=$H18,W18,"") | AE18: =IF(AE$3=$H18,X18,"") -> -12 | AH18: =MAXIFS(AB18:AE18,AB18:AE18, ">-1") -> 0 | AI18: =MINIFS(AB18:AE18,AB18:AE18, "<0") -> -12 | AK18: =IF(U18>0,AK$3,"") -> Thomas | AL18: =IF(V18>0,AL$3,"") -> Peter | AM18: =IF(W18>0,AM$3,"") | AN18: =IF(X18>0,AN$3,"") | AO18: =COUNTif(AK18:AN18,">0"&"*") -> 2 | AP18: =H18 -> Christian | AQ18: =IFERROR(__xludf.DUMMYFUNCTION("IFNA(QUERY(transpose(AY18:BB18),""Select Col1 where Col1 is not null limit 1"",0))"),"Janus") -> Janus | AS18: =IF(AK18=AS$3,"",AS$3) | AT18: =IF(AL18=AT$3,"",AT$3) | AU18: =IF(AM18=AU$3,"",AU$3) -> Janus | AV18: =IF(AN18=AV$3,"",AV$3) -> Christian | AW18: =COUNTif(AS18:AV18,">0"&"*") -> 2 | AX18: =sum(AB18:AE18) -> -12 | AY18: =IFNA(IFS(AY$3=$AP18,"",$AX18=U18,AY$3),"") | AZ18: =IFNA(IFS(AZ$3=$AP18,"",$AX18=V18,AZ$3),"") | BA18: =IFNA(IFS(BA$3=$AP18,"",$AX18=W18,BA$3),"") -> Janus | BB18: =IFNA(IFS(BB$3=$AP18,"",$AX18=X18,BB$3),"") | BC18: =OFFSET('00_Regnskab_01'!$A$1,MATCH(A18,'00_Regnskab_01'!$A$1:$A$25)-1,2) -> 43407 | BE18: =if(U18>0,1+BE17,0) -> 1 | BF18: =if(V18>0,1+BF17,0) -> 2 | BG18: =if(W18>0,1+BG17,0) -> 0 | BH18: =if(X18>0,1+BH17,0) -> 0 | BJ18: =if(U18<0,1+BJ17,0) -> 0 | BK18: =if(V18<0,1+BK17,0) -> 0 | BL18: =if(W18<0,1+BL17,0) -> 2 | BM18: =if(X18<0,1+BM17,0) -> 1 | BO18: =if(U18>0,U18+BO17,0) -> 12 | BP18: =if(V18>0,V18+BP17,0) -> 172 | BQ18: =if(W18>0,W18+BQ17,0) -> 0 | BR18: =if(X18>0,X18+BR17,0) -> 0 | BT18: =if(U18<0,U18+BT17,0) -> 0 | BU18: =if(V18<0,V18+BU17,0) -> 0 | BV18: =if(W18<0,W18+BV17,0) -> -172 | BW18: =if(X18<0,X18+BW17,0) -> -12 | BY18: 14
A19: 8 | B19: ='08_3-11-2018'!A11 -> 9 | C19: ='08_3-11-2018'!B11 -> -148 | D19: ='08_3-11-2018'!D11 -> 12 | E19: ='08_3-11-2018'!C11 -> -44 | F19: ='08_3-11-2018'!E11 -> 180 | G19: ='08_3-11-2018'!F11 -> 0 | H19: ='08_3-11-2018'!G11 -> Peter | J19: ='08_3-11-2018'!H11 -> Christian | K19: ='08_3-11-2018'!I11 | U19: =C19-C18 -> -64 | V19: =D19-D18 -> -64 | W19: =E19-E18 -> 64 | X19: =F19-F18 -> 64 | AB19: =IF(AB$3=$H19,U19,"") | AC19: =IF(AC$3=$H19,V19,"") -> -64 | AD19: =IF(AD$3=$H19,W19,"") | AE19: =IF(AE$3=$H19,X19,"") | AH19: =MAXIFS(AB19:AE19,AB19:AE19, ">-1") -> 0 | AI19: =MINIFS(AB19:AE19,AB19:AE19, "<0") -> -64 | AK19: =IF(U19>0,AK$3,"") | AL19: =IF(V19>0,AL$3,"") | AM19: =IF(W19>0,AM$3,"") -> Janus | AN19: =IF(X19>0,AN$3,"") -> Christian | AO19: =COUNTif(AK19:AN19,">0"&"*") -> 2 | AP19: =H19 -> Peter | AQ19: =IFERROR(__xludf.DUMMYFUNCTION("IFNA(QUERY(transpose(AY19:BB19),""Select Col1 where Col1 is not null limit 1"",0))"),"Thomas") -> Thomas | AS19: =IF(AK19=AS$3,"",AS$3) -> Thomas | AT19: =IF(AL19=AT$3,"",AT$3) -> Peter | AU19: =IF(AM19=AU$3,"",AU$3) | AV19: =IF(AN19=AV$3,"",AV$3) | AW19: =COUNTif(AS19:AV19,">0"&"*") -> 2 | AX19: =sum(AB19:AE19) -> -64 | AY19: =IFNA(IFS(AY$3=$AP19,"",$AX19=U19,AY$3),"") -> Thomas | AZ19: =IFNA(IFS(AZ$3=$AP19,"",$AX19=V19,AZ$3),"") | BA19: =IFNA(IFS(BA$3=$AP19,"",$AX19=W19,BA$3),"") | BB19: =IFNA(IFS(BB$3=$AP19,"",$AX19=X19,BB$3),"") | BC19: =OFFSET('00_Regnskab_01'!$A$1,MATCH(A19,'00_Regnskab_01'!$A$1:$A$25)-1,2) -> 43407 | BE19: =if(U19>0,1+BE18,0) -> 0 | BF19: =if(V19>0,1+BF18,0) -> 0 | BG19: =if(W19>0,1+BG18,0) -> 1 | BH19: =if(X19>0,1+BH18,0) -> 1 | BJ19: =if(U19<0,1+BJ18,0) -> 1 | BK19: =if(V19<0,1+BK18,0) -> 1 | BL19: =if(W19<0,1+BL18,0) -> 0 | BM19: =if(X19<0,1+BM18,0) -> 0 | BO19: =if(U19>0,U19+BO18,0) -> 0 | BP19: =if(V19>0,V19+BP18,0) -> 0 | BQ19: =if(W19>0,W19+BQ18,0) -> 64 | BR19: =if(X19>0,X19+BR18,0) -> 64 | BT19: =if(U19<0,U19+BT18,0) -> -64 | BU19: =if(V19<0,V19+BU18,0) -> -64 | BV19: =if(W19<0,W19+BV18,0) -> 0 | BW19: =if(X19<0,X19+BW18,0) -> 0 | BY19: 15
A20: 8 | B20: ='08_3-11-2018'!A12 -> 10 | C20: ='08_3-11-2018'!B12 -> -84 | D20: ='08_3-11-2018'!D12 -> -52 | E20: ='08_3-11-2018'!C12 -> 20 | F20: ='08_3-11-2018'!E12 -> 116 | G20: ='08_3-11-2018'!F12 -> 0 | H20: ='08_3-11-2018'!G12 -> Thomas | J20: ='08_3-11-2018'!H12 -> Thomas | K20: ='08_3-11-2018'!I12 | U20: =C20-C19 -> 64 | V20: =D20-D19 -> -64 | W20: =E20-E19 -> 64 | X20: =F20-F19 -> -64 | AB20: =IF(AB$3=$H20,U20,"") -> 64 | AC20: =IF(AC$3=$H20,V20,"") | AD20: =IF(AD$3=$H20,W20,"") | AE20: =IF(AE$3=$H20,X20,"") | AH20: =MAXIFS(AB20:AE20,AB20:AE20, ">-1") -> 64 | AI20: =MINIFS(AB20:AE20,AB20:AE20, "<0") -> 0 | AK20: =IF(U20>0,AK$3,"") -> Thomas | AL20: =IF(V20>0,AL$3,"") | AM20: =IF(W20>0,AM$3,"") -> Janus | AN20: =IF(X20>0,AN$3,"") | AO20: =COUNTif(AK20:AN20,">0"&"*") -> 2 | AP20: =H20 -> Thomas | AQ20: =IFERROR(__xludf.DUMMYFUNCTION("IFNA(QUERY(transpose(AY20:BB20),""Select Col1 where Col1 is not null limit 1"",0))"),"Janus") -> Janus | AS20: =IF(AK20=AS$3,"",AS$3) | AT20: =IF(AL20=AT$3,"",AT$3) -> Peter | AU20: =IF(AM20=AU$3,"",AU$3) | AV20: =IF(AN20=AV$3,"",AV$3) -> Christian | AW20: =COUNTif(AS20:AV20,">0"&"*") -> 2 | AX20: =sum(AB20:AE20) -> 64 | AY20: =IFNA(IFS(AY$3=$AP20,"",$AX20=U20,AY$3),"") | AZ20: =IFNA(IFS(AZ$3=$AP20,"",$AX20=V20,AZ$3),"") | BA20: =IFNA(IFS(BA$3=$AP20,"",$AX20=W20,BA$3),"") -> Janus | BB20: =IFNA(IFS(BB$3=$AP20,"",$AX20=X20,BB$3),"") | BC20: =OFFSET('00_Regnskab_01'!$A$1,MATCH(A20,'00_Regnskab_01'!$A$1:$A$25)-1,2) -> 43407 | BE20: =if(U20>0,1+BE19,0) -> 1 | BF20: =if(V20>0,1+BF19,0) -> 0 | BG20: =if(W20>0,1+BG19,0) -> 2 | BH20: =if(X20>0,1+BH19,0) -> 0 | BJ20: =if(U20<0,1+BJ19,0) -> 0 | BK20: =if(V20<0,1+BK19,0) -> 2 | BL20: =if(W20<0,1+BL19,0) -> 0 | BM20: =if(X20<0,1+BM19,0) -> 1 | BO20: =if(U20>0,U20+BO19,0) -> 64 | BP20: =if(V20>0,V20+BP19,0) -> 0 | BQ20: =if(W20>0,W20+BQ19,0) -> 128 | BR20: =if(X20>0,X20+BR19,0) -> 0 | BT20: =if(U20<0,U20+BT19,0) -> 0 | BU20: =if(V20<0,V20+BU19,0) -> -128 | BV20: =if(W20<0,W20+BV19,0) -> 0 | BW20: =if(X20<0,X20+BW19,0) -> -64 | BY20: 16
A21: 8 | B21: ='08_3-11-2018'!A13 -> 11 | C21: ='08_3-11-2018'!B13 -> -44 | D21: ='08_3-11-2018'!D13 -> -12 | E21: ='08_3-11-2018'!C13 -> -20 | F21: ='08_3-11-2018'!E13 -> 76 | G21: ='08_3-11-2018'!F13 -> 0 | H21: ='08_3-11-2018'!G13 -> Thomas | J21: ='08_3-11-2018'!H13 -> Janus | K21: ='08_3-11-2018'!I13 | U21: =C21-C20 -> 40 | V21: =D21-D20 -> 40 | W21: =E21-E20 -> -40 | X21: =F21-F20 -> -40 | AB21: =IF(AB$3=$H21,U21,"") -> 40 | AC21: =IF(AC$3=$H21,V21,"") | AD21: =IF(AD$3=$H21,W21,"") | AE21: =IF(AE$3=$H21,X21,"") | AH21: =MAXIFS(AB21:AE21,AB21:AE21, ">-1") -> 40 | AI21: =MINIFS(AB21:AE21,AB21:AE21, "<0") -> 0 | AK21: =IF(U21>0,AK$3,"") -> Thomas | AL21: =IF(V21>0,AL$3,"") -> Peter | AM21: =IF(W21>0,AM$3,"") | AN21: =IF(X21>0,AN$3,"") | AO21: =COUNTif(AK21:AN21,">0"&"*") -> 2 | AP21: =H21 -> Thomas | AQ21: =IFERROR(__xludf.DUMMYFUNCTION("IFNA(QUERY(transpose(AY21:BB21),""Select Col1 where Col1 is not null limit 1"",0))"),"Peter") -> Peter | AS21: =IF(AK21=AS$3,"",AS$3) | AT21: =IF(AL21=AT$3,"",AT$3) | AU21: =IF(AM21=AU$3,"",AU$3) -> Janus | AV21: =IF(AN21=AV$3,"",AV$3) -> Christian | AW21: =COUNTif(AS21:AV21,">0"&"*") -> 2 | AX21: =sum(AB21:AE21) -> 40 | AY21: =IFNA(IFS(AY$3=$AP21,"",$AX21=U21,AY$3),"") | AZ21: =IFNA(IFS(AZ$3=$AP21,"",$AX21=V21,AZ$3),"") -> Peter | BA21: =IFNA(IFS(BA$3=$AP21,"",$AX21=W21,BA$3),"") | BB21: =IFNA(IFS(BB$3=$AP21,"",$AX21=X21,BB$3),"") | BC21: =OFFSET('00_Regnskab_01'!$A$1,MATCH(A21,'00_Regnskab_01'!$A$1:$A$25)-1,2) -> 43407 | BE21: =if(U21>0,1+BE20,0) -> 2 | BF21: =if(V21>0,1+BF20,0) -> 1 | BG21: =if(W21>0,1+BG20,0) -> 0 | BH21: =if(X21>0,1+BH20,0) -> 0 | BJ21: =if(U21<0,1+BJ20,0) -> 0 | BK21: =if(V21<0,1+BK20,0) -> 0 | BL21: =if(W21<0,1+BL20,0) -> 1 | BM21: =if(X21<0,1+BM20,0) -> 2 | BO21: =if(U21>0,U21+BO20,0) -> 104 | BP21: =if(V21>0,V21+BP20,0) -> 40 | BQ21: =if(W21>0,W21+BQ20,0) -> 0 | BR21: =if(X21>0,X21+BR20,0) -> 0 | BT21: =if(U21<0,U21+BT20,0) -> 0 | BU21: =if(V21<0,V21+BU20,0) -> 0 | BV21: =if(W21<0,W21+BV20,0) -> -40 | BW21: =if(X21<0,X21+BW20,0) -> -104 | BY21: 17
A22: 8 | B22: ='08_3-11-2018'!A14 -> 12 | C22: ='08_3-11-2018'!B14 -> -20 | D22: ='08_3-11-2018'!D14 -> -20 | E22: ='08_3-11-2018'!C14 -> -28 | F22: ='08_3-11-2018'!E14 -> 68 | G22: ='08_3-11-2018'!F14 -> 0 | H22: ='08_3-11-2018'!G14 -> Thomas | J22: ='08_3-11-2018'!H14 -> Peter | K22: ='08_3-11-2018'!I14 | U22: =C22-C21 -> 24 | V22: =D22-D21 -> -8 | W22: =E22-E21 -> -8 | X22: =F22-F21 -> -8 | AB22: =IF(AB$3=$H22,U22,"") -> 24 | AC22: =IF(AC$3=$H22,V22,"") | AD22: =IF(AD$3=$H22,W22,"") | AE22: =IF(AE$3=$H22,X22,"") | AH22: =MAXIFS(AB22:AE22,AB22:AE22, ">-1") -> 24 | AI22: =MINIFS(AB22:AE22,AB22:AE22, "<0") -> 0 | AK22: =IF(U22>0,AK$3,"") -> Thomas | AL22: =IF(V22>0,AL$3,"") | AM22: =IF(W22>0,AM$3,"") | AN22: =IF(X22>0,AN$3,"") | AO22: =COUNTif(AK22:AN22,">0"&"*") -> 1 | AP22: =H22 -> Thomas | AQ22: =IFERROR(__xludf.DUMMYFUNCTION("IFNA(QUERY(transpose(AY22:BB22),""Select Col1 where Col1 is not null limit 1"",0))"),"") | AS22: =IF(AK22=AS$3,"",AS$3) | AT22: =IF(AL22=AT$3,"",AT$3) -> Peter | AU22: =IF(AM22=AU$3,"",AU$3) -> Janus | AV22: =IF(AN22=AV$3,"",AV$3) -> Christian | AW22: =COUNTif(AS22:AV22,">0"&"*") -> 3 | AX22: =sum(AB22:AE22) -> 24 | AY22: =IFNA(IFS(AY$3=$AP22,"",$AX22=U22,AY$3),"") | AZ22: =IFNA(IFS(AZ$3=$AP22,"",$AX22=V22,AZ$3),"") | BA22: =IFNA(IFS(BA$3=$AP22,"",$AX22=W22,BA$3),"") | BB22: =IFNA(IFS(BB$3=$AP22,"",$AX22=X22,BB$3),"") | BC22: =OFFSET('00_Regnskab_01'!$A$1,MATCH(A22,'00_Regnskab_01'!$A$1:$A$25)-1,2) -> 43407 | BE22: =if(U22>0,1+BE21,0) -> 3 | BF22: =if(V22>0,1+BF21,0) -> 0 | BG22: =if(W22>0,1+BG21,0) -> 0 | BH22: =if(X22>0,1+BH21,0) -> 0 | BJ22: =if(U22<0,1+BJ21,0) -> 0 | BK22: =if(V22<0,1+BK21,0) -> 1 | BL22: =if(W22<0,1+BL21,0) -> 2 | BM22: =if(X22<0,1+BM21,0) -> 3 | BO22: =if(U22>0,U22+BO21,0) -> 128 | BP22: =if(V22>0,V22+BP21,0) -> 0 | BQ22: =if(W22>0,W22+BQ21,0) -> 0 | BR22: =if(X22>0,X22+BR21,0) -> 0 | BT22: =if(U22<0,U22+BT21,0) -> 0 | BU22: =if(V22<0,V22+BU21,0) -> -8 | BV22: =if(W22<0,W22+BV21,0) -> -48 | BW22: =if(X22<0,X22+BW21,0) -> -112 | BY22: 18
A23: 8 | B23: ='08_3-11-2018'!A15 -> 13 | C23: ='08_3-11-2018'!B15 -> 4 | D23: ='08_3-11-2018'!D15 -> -28 | E23: ='08_3-11-2018'!C15 -> -36 | F23: ='08_3-11-2018'!E15 -> 60 | G23: ='08_3-11-2018'!F15 -> 0 | H23: ='08_3-11-2018'!G15 -> Thomas | J23: ='08_3-11-2018'!H15 -> Christian | K23: ='08_3-11-2018'!I15 | U23: =C23-C22 -> 24 | V23: =D23-D22 -> -8 | W23: =E23-E22 -> -8 | X23: =F23-F22 -> -8 | AB23: =IF(AB$3=$H23,U23,"") -> 24 | AC23: =IF(AC$3=$H23,V23,"") | AD23: =IF(AD$3=$H23,W23,"") | AE23: =IF(AE$3=$H23,X23,"") | AH23: =MAXIFS(AB23:AE23,AB23:AE23, ">-1") -> 24 | AI23: =MINIFS(AB23:AE23,AB23:AE23, "<0") -> 0 | AK23: =IF(U23>0,AK$3,"") -> Thomas | AL23: =IF(V23>0,AL$3,"") | AM23: =IF(W23>0,AM$3,"") | AN23: =IF(X23>0,AN$3,"") | AO23: =COUNTif(AK23:AN23,">0"&"*") -> 1 | AP23: =H23 -> Thomas | AQ23: =IFERROR(__xludf.DUMMYFUNCTION("IFNA(QUERY(transpose(AY23:BB23),""Select Col1 where Col1 is not null limit 1"",0))"),"") | AS23: =IF(AK23=AS$3,"",AS$3) | AT23: =IF(AL23=AT$3,"",AT$3) -> Peter | AU23: =IF(AM23=AU$3,"",AU$3) -> Janus | AV23: =IF(AN23=AV$3,"",AV$3) -> Christian | AW23: =COUNTif(AS23:AV23,">0"&"*") -> 3 | AX23: =sum(AB23:AE23) -> 24 | AY23: =IFNA(IFS(AY$3=$AP23,"",$AX23=U23,AY$3),"") | AZ23: =IFNA(IFS(AZ$3=$AP23,"",$AX23=V23,AZ$3),"") | BA23: =IFNA(IFS(BA$3=$AP23,"",$AX23=W23,BA$3),"") | BB23: =IFNA(IFS(BB$3=$AP23,"",$AX23=X23,BB$3),"") | BC23: =OFFSET('00_Regnskab_01'!$A$1,MATCH(A23,'00_Regnskab_01'!$A$1:$A$25)-1,2) -> 43407 | BE23: =if(U23>0,1+BE22,0) -> 4 | BF23: =if(V23>0,1+BF22,0) -> 0 | BG23: =if(W23>0,1+BG22,0) -> 0 | BH23: =if(X23>0,1+BH22,0) -> 0 | BJ23: =if(U23<0,1+BJ22,0) -> 0 | BK23: =if(V23<0,1+BK22,0) -> 2 | BL23: =if(W23<0,1+BL22,0) -> 3 | BM23: =if(X23<0,1+BM22,0) -> 4 | BO23: =if(U23>0,U23+BO22,0) -> 152 | BP23: =if(V23>0,V23+BP22,0) -> 0 | BQ23: =if(W23>0,W23+BQ22,0) -> 0 | BR23: =if(X23>0,X23+BR22,0) -> 0 | BT23: =if(U23<0,U23+BT22,0) -> 0 | BU23: =if(V23<0,V23+BU22,0) -> -16 | BV23: =if(W23<0,W23+BV22,0) -> -56 | BW23: =if(X23<0,X23+BW22,0) -> -120 | BY23: 19
A24: 8 | B24: ='08_3-11-2018'!A16 -> 14 | C24: ='08_3-11-2018'!B16 -> -8 | D24: ='08_3-11-2018'!D16 -> -40 | E24: ='08_3-11-2018'!C16 -> -24 | F24: ='08_3-11-2018'!E16 -> 72 | G24: ='08_3-11-2018'!F16 -> 0 | H24: ='08_3-11-2018'!G16 -> Janus | J24: ='08_3-11-2018'!H16 -> Thomas | K24: ='08_3-11-2018'!I16 | U24: =C24-C23 -> -12 | V24: =D24-D23 -> -12 | W24: =E24-E23 -> 12 | X24: =F24-F23 -> 12 | AB24: =IF(AB$3=$H24,U24,"") | AC24: =IF(AC$3=$H24,V24,"") | AD24: =IF(AD$3=$H24,W24,"") -> 12 | AE24: =IF(AE$3=$H24,X24,"") | AH24: =MAXIFS(AB24:AE24,AB24:AE24, ">-1") -> 12 | AI24: =MINIFS(AB24:AE24,AB24:AE24, "<0") -> 0 | AK24: =IF(U24>0,AK$3,"") | AL24: =IF(V24>0,AL$3,"") | AM24: =IF(W24>0,AM$3,"") -> Janus | AN24: =IF(X24>0,AN$3,"") -> Christian | AO24: =COUNTif(AK24:AN24,">0"&"*") -> 2 | AP24: =H24 -> Janus | AQ24: =IFERROR(__xludf.DUMMYFUNCTION("IFNA(QUERY(transpose(AY24:BB24),""Select Col1 where Col1 is not null limit 1"",0))"),"Christian") -> Christian | AS24: =IF(AK24=AS$3,"",AS$3) -> Thomas | AT24: =IF(AL24=AT$3,"",AT$3) -> Peter | AU24: =IF(AM24=AU$3,"",AU$3) | AV24: =IF(AN24=AV$3,"",AV$3) | AW24: =COUNTif(AS24:AV24,">0"&"*") -> 2 | AX24: =sum(AB24:AE24) -> 12 | AY24: =IFNA(IFS(AY$3=$AP24,"",$AX24=U24,AY$3),"") | AZ24: =IFNA(IFS(AZ$3=$AP24,"",$AX24=V24,AZ$3),"") | BA24: =IFNA(IFS(BA$3=$AP24,"",$AX24=W24,BA$3),"") | BB24: =IFNA(IFS(BB$3=$AP24,"",$AX24=X24,BB$3),"") -> Christian | BC24: =OFFSET('00_Regnskab_01'!$A$1,MATCH(A24,'00_Regnskab_01'!$A$1:$A$25)-1,2) -> 43407 | BE24: =if(U24>0,1+BE23,0) -> 0 | BF24: =if(V24>0,1+BF23,0) -> 0 | BG24: =if(W24>0,1+BG23,0) -> 1 | BH24: =if(X24>0,1+BH23,0) -> 1 | BJ24: =if(U24<0,1+BJ23,0) -> 1 | BK24: =if(V24<0,1+BK23,0) -> 3 | BL24: =if(W24<0,1+BL23,0) -> 0 | BM24: =if(X24<0,1+BM23,0) -> 0 | BO24: =if(U24>0,U24+BO23,0) -> 0 | BP24: =if(V24>0,V24+BP23,0) -> 0 | BQ24: =if(W24>0,W24+BQ23,0) -> 12 | BR24: =if(X24>0,X24+BR23,0) -> 12 | BT24: =if(U24<0,U24+BT23,0) -> -12 | BU24: =if(V24<0,V24+BU23,0) -> -28 | BV24: =if(W24<0,W24+BV23,0) -> 0 | BW24: =if(X24<0,X24+BW23,0) -> 0 | BY24: 20
A25: 8 | B25: ='08_3-11-2018'!A17 -> 15 | C25: ='08_3-11-2018'!B17 -> 12 | D25: ='08_3-11-2018'!D17 -> -20 | E25: ='08_3-11-2018'!C17 -> -4 | F25: ='08_3-11-2018'!E17 -> 12 | G25: ='08_3-11-2018'!F17 -> 0 | H25: ='08_3-11-2018'!G17 -> Christian | J25: ='08_3-11-2018'!H17 -> Janus | K25: ='08_3-11-2018'!I17 | U25: =C25-C24 -> 20 | V25: =D25-D24 -> 20 | W25: =E25-E24 -> 20 | X25: =F25-F24 -> -60 | AB25: =IF(AB$3=$H25,U25,"") | AC25: =IF(AC$3=$H25,V25,"") | AD25: =IF(AD$3=$H25,W25,"") | AE25: =IF(AE$3=$H25,X25,"") -> -60 | AH25: =MAXIFS(AB25:AE25,AB25:AE25, ">-1") -> 0 | AI25: =MINIFS(AB25:AE25,AB25:AE25, "<0") -> -60 | AK25: =IF(U25>0,AK$3,"") -> Thomas | AL25: =IF(V25>0,AL$3,"") -> Peter | AM25: =IF(W25>0,AM$3,"") -> Janus | AN25: =IF(X25>0,AN$3,"") | AO25: =COUNTif(AK25:AN25,">0"&"*") -> 3 | AP25: =H25 -> Christian | AQ25: =IFERROR(__xludf.DUMMYFUNCTION("IFNA(QUERY(transpose(AY25:BB25),""Select Col1 where Col1 is not null limit 1"",0))"),"") | AS25: =IF(AK25=AS$3,"",AS$3) | AT25: =IF(AL25=AT$3,"",AT$3) | AU25: =IF(AM25=AU$3,"",AU$3) | AV25: =IF(AN25=AV$3,"",AV$3) -> Christian | AW25: =COUNTif(AS25:AV25,">0"&"*") -> 1 | AX25: =sum(AB25:AE25) -> -60 | AY25: =IFNA(IFS(AY$3=$AP25,"",$AX25=U25,AY$3),"") | AZ25: =IFNA(IFS(AZ$3=$AP25,"",$AX25=V25,AZ$3),"") | BA25: =IFNA(IFS(BA$3=$AP25,"",$AX25=W25,BA$3),"") | BB25: =IFNA(IFS(BB$3=$AP25,"",$AX25=X25,BB$3),"") | BC25: =OFFSET('00_Regnskab_01'!$A$1,MATCH(A25,'00_Regnskab_01'!$A$1:$A$25)-1,2) -> 43407 | BE25: =if(U25>0,1+BE24,0) -> 1 | BF25: =if(V25>0,1+BF24,0) -> 1 | BG25: =if(W25>0,1+BG24,0) -> 2 | BH25: =if(X25>0,1+BH24,0) -> 0 | BJ25: =if(U25<0,1+BJ24,0) -> 0 | BK25: =if(V25<0,1+BK24,0) -> 0 | BL25: =if(W25<0,1+BL24,0) -> 0 | BM25: =if(X25<0,1+BM24,0) -> 1 | BO25: =if(U25>0,U25+BO24,0) -> 20 | BP25: =if(V25>0,V25+BP24,0) -> 20 | BQ25: =if(W25>0,W25+BQ24,0) -> 32 | BR25: =if(X25>0,X25+BR24,0) -> 0 | BT25: =if(U25<0,U25+BT24,0) -> 0 | BU25: =if(V25<0,V25+BU24,0) -> 0 | BV25: =if(W25<0,W25+BV24,0) -> 0 | BW25: =if(X25<0,X25+BW24,0) -> -60 | BY25: 21
A26: 8 | B26: ='08_3-11-2018'!A18 -> 16 | C26: ='08_3-11-2018'!B18 -> 20 | D26: ='08_3-11-2018'!D18 -> -12 | E26: ='08_3-11-2018'!C18 -> -12 | F26: ='08_3-11-2018'!E18 -> 4 | G26: ='08_3-11-2018'!F18 -> 0 | H26: ='08_3-11-2018'!G18 -> Janus | I26: Christian | J26: ='08_3-11-2018'!H18 -> Peter | K26: ='08_3-11-2018'!I18 -> 9 halve | M26: 9 | N26: Halve | U26: =C26-C25 -> 8 | V26: =D26-D25 -> 8 | W26: =E26-E25 -> -8 | X26: =F26-F25 -> -8 | AB26: =IF(AB$3=$H26,U26,"") | AC26: =IF(AC$3=$H26,V26,"") | AD26: =IF(AD$3=$H26,W26,"") -> -8 | AE26: =IF(AE$3=$H26,X26,"") | AH26: =MAXIFS(AB26:AE26,AB26:AE26, ">-1") -> 0 | AI26: =MINIFS(AB26:AE26,AB26:AE26, "<0") -> -8 | AK26: =IF(U26>0,AK$3,"") -> Thomas | AL26: =IF(V26>0,AL$3,"") -> Peter | AM26: =IF(W26>0,AM$3,"") | AN26: =IF(X26>0,AN$3,"") | AO26: =COUNTif(AK26:AN26,">0"&"*") -> 2 | AP26: =H26 -> Janus | AQ26: =IFERROR(__xludf.DUMMYFUNCTION("IFNA(QUERY(transpose(AY26:BB26),""Select Col1 where Col1 is not null limit 1"",0))"),"Christian") -> Christian | AS26: =IF(AK26=AS$3,"",AS$3) | AT26: =IF(AL26=AT$3,"",AT$3) | AU26: =IF(AM26=AU$3,"",AU$3) -> Janus | AV26: =IF(AN26=AV$3,"",AV$3) -> Christian | AW26: =COUNTif(AS26:AV26,">0"&"*") -> 2 | AX26: =sum(AB26:AE26) -> -8 | AY26: =IFNA(IFS(AY$3=$AP26,"",$AX26=U26,AY$3),"") | AZ26: =IFNA(IFS(AZ$3=$AP26,"",$AX26=V26,AZ$3),"") | BA26: =IFNA(IFS(BA$3=$AP26,"",$AX26=W26,BA$3),"") | BB26: =IFNA(IFS(BB$3=$AP26,"",$AX26=X26,BB$3),"") -> Christian | BC26: =OFFSET('00_Regnskab_01'!$A$1,MATCH(A26,'00_Regnskab_01'!$A$1:$A$25)-1,2) -> 43407 | BE26: =if(U26>0,1+BE25,0) -> 2 | BF26: =if(V26>0,1+BF25,0) -> 2 | BG26: =if(W26>0,1+BG25,0) -> 0 | BH26: =if(X26>0,1+BH25,0) -> 0 | BJ26: =if(U26<0,1+BJ25,0) -> 0 | BK26: =if(V26<0,1+BK25,0) -> 0 | BL26: =if(W26<0,1+BL25,0) -> 1 | BM26: =if(X26<0,1+BM25,0) -> 2 | BO26: =if(U26>0,U26+BO25,0) -> 28 | BP26: =if(V26>0,V26+BP25,0) -> 28 | BQ26: =if(W26>0,W26+BQ25,0) -> 0 | BR26: =if(X26>0,X26+BR25,0) -> 0 | BT26: =if(U26<0,U26+BT25,0) -> 0 | BU26: =if(V26<0,V26+BU25,0) -> 0 | BV26: =if(W26<0,W26+BV25,0) -> -8 | BW26: =if(X26<0,X26+BW25,0) -> -68 | BY26: 22
A27: 8 | B27: ='08_3-11-2018'!A19 -> 17 | C27: ='08_3-11-2018'!B19 -> -28 | D27: ='08_3-11-2018'!D19 -> 36 | E27: ='08_3-11-2018'!C19 -> -60 | F27: ='08_3-11-2018'!E19 -> 52 | G27: ='08_3-11-2018'!F19 -> 0 | H27: ='08_3-11-2018'!G19 -> Thomas | J27: ='08_3-11-2018'!H19 -> Christian | K27: ='08_3-11-2018'!I19 -> 9 vip i 3. | M27: 9 | N27: Vip | O27: 3 | U27: =C27-C26 -> -48 | V27: =D27-D26 -> 48 | W27: =E27-E26 -> -48 | X27: =F27-F26 -> 48 | AB27: =IF(AB$3=$H27,U27,"") -> -48 | AC27: =IF(AC$3=$H27,V27,"") | AD27: =IF(AD$3=$H27,W27,"") | AE27: =IF(AE$3=$H27,X27,"") | AH27: =MAXIFS(AB27:AE27,AB27:AE27, ">-1") -> 0 | AI27: =MINIFS(AB27:AE27,AB27:AE27, "<0") -> -48 | AK27: =IF(U27>0,AK$3,"") | AL27: =IF(V27>0,AL$3,"") -> Peter | AM27: =IF(W27>0,AM$3,"") | AN27: =IF(X27>0,AN$3,"") -> Christian | AO27: =COUNTif(AK27:AN27,">0"&"*") -> 2 | AP27: =H27 -> Thomas | AQ27: =IFERROR(__xludf.DUMMYFUNCTION("IFNA(QUERY(transpose(AY27:BB27),""Select Col1 where Col1 is not null limit 1"",0))"),"Janus") -> Janus | AS27: =IF(AK27=AS$3,"",AS$3) -> Thomas | AT27: =IF(AL27=AT$3,"",AT$3) | AU27: =IF(AM27=AU$3,"",AU$3) -> Janus | AV27: =IF(AN27=AV$3,"",AV$3) | AW27: =COUNTif(AS27:AV27,">0"&"*") -> 2 | AX27: =sum(AB27:AE27) -> -48 | AY27: =IFNA(IFS(AY$3=$AP27,"",$AX27=U27,AY$3),"") | AZ27: =IFNA(IFS(AZ$3=$AP27,"",$AX27=V27,AZ$3),"") | BA27: =IFNA(IFS(BA$3=$AP27,"",$AX27=W27,BA$3),"") -> Janus | BB27: =IFNA(IFS(BB$3=$AP27,"",$AX27=X27,BB$3),"") | BC27: =OFFSET('00_Regnskab_01'!$A$1,MATCH(A27,'00_Regnskab_01'!$A$1:$A$25)-1,2) -> 43407 | BE27: =if(U27>0,1+BE26,0) -> 0 | BF27: =if(V27>0,1+BF26,0) -> 3 | BG27: =if(W27>0,1+BG26,0) -> 0 | BH27: =if(X27>0,1+BH26,0) -> 1 | BJ27: =if(U27<0,1+BJ26,0) -> 1 | BK27: =if(V27<0,1+BK26,0) -> 0 | BL27: =if(W27<0,1+BL26,0) -> 2 | BM27: =if(X27<0,1+BM26,0) -> 0 | BO27: =if(U27>0,U27+BO26,0) -> 0 | BP27: =if(V27>0,V27+BP26,0) -> 76 | BQ27: =if(W27>0,W27+BQ26,0) -> 0 | BR27: =if(X27>0,X27+BR26,0) -> 48 | BT27: =if(U27<0,U27+BT26,0) -> -48 | BU27: =if(V27<0,V27+BU26,0) -> 0 | BV27: =if(W27<0,W27+BV26,0) -> -56 | BW27: =if(X27<0,X27+BW26,0) -> 0 | BY27: 23
